ERROR 2023-12-15 19:02:21,808 log Internal Server Error: /api/products/
Traceback (most recent call last):
  File "/Users/aliosmanyilmaz/opt/anaconda3/envs/shoe/lib/python3.12/site-packages/django/core/handlers/exception.py", line 55, in inner
    response = get_response(request)
               ^^^^^^^^^^^^^^^^^^^^^
  File "/Users/aliosmanyilmaz/opt/anaconda3/envs/shoe/lib/python3.12/site-packages/django/core/handlers/base.py", line 197, in _get_response
    response = wrapped_callback(request, *callback_args, **callback_kwargs)
               ^^^^^^^^^^^^^^^^^^^^^^^^^^^^^^^^^^^^^^^^^^^^^^^^^^^^^^^^^^^^
  File "/Users/aliosmanyilmaz/opt/anaconda3/envs/shoe/lib/python3.12/site-packages/sentry_sdk/integrations/django/views.py", line 84, in sentry_wrapped_callback
    return callback(request, *args, **kwargs)
           ^^^^^^^^^^^^^^^^^^^^^^^^^^^^^^^^^^
  File "/Users/aliosmanyilmaz/opt/anaconda3/envs/shoe/lib/python3.12/site-packages/django/views/decorators/csrf.py", line 56, in wrapper_view
    return view_func(*args, **kwargs)
           ^^^^^^^^^^^^^^^^^^^^^^^^^^
  File "/Users/aliosmanyilmaz/opt/anaconda3/envs/shoe/lib/python3.12/site-packages/rest_framework/viewsets.py", line 125, in view
    return self.dispatch(request, *args, **kwargs)
           ^^^^^^^^^^^^^^^^^^^^^^^^^^^^^^^^^^^^^^^
  File "/Users/aliosmanyilmaz/opt/anaconda3/envs/shoe/lib/python3.12/site-packages/rest_framework/views.py", line 509, in dispatch
    response = self.handle_exception(exc)
               ^^^^^^^^^^^^^^^^^^^^^^^^^^
  File "/Users/aliosmanyilmaz/opt/anaconda3/envs/shoe/lib/python3.12/site-packages/rest_framework/views.py", line 469, in handle_exception
    self.raise_uncaught_exception(exc)
  File "/Users/aliosmanyilmaz/opt/anaconda3/envs/shoe/lib/python3.12/site-packages/rest_framework/views.py", line 480, in raise_uncaught_exception
    raise exc
  File "/Users/aliosmanyilmaz/opt/anaconda3/envs/shoe/lib/python3.12/site-packages/rest_framework/views.py", line 506, in dispatch
    response = handler(request, *args, **kwargs)
               ^^^^^^^^^^^^^^^^^^^^^^^^^^^^^^^^^
  File "/Users/aliosmanyilmaz/opt/anaconda3/envs/shoe/lib/python3.12/site-packages/rest_framework/mixins.py", line 46, in list
    return Response(serializer.data)
                    ^^^^^^^^^^^^^^^
  File "/Users/aliosmanyilmaz/opt/anaconda3/envs/shoe/lib/python3.12/site-packages/rest_framework/serializers.py", line 768, in data
    ret = super().data
          ^^^^^^^^^^^^
  File "/Users/aliosmanyilmaz/opt/anaconda3/envs/shoe/lib/python3.12/site-packages/rest_framework/serializers.py", line 253, in data
    self._data = self.to_representation(self.instance)
                 ^^^^^^^^^^^^^^^^^^^^^^^^^^^^^^^^^^^^^
  File "/Users/aliosmanyilmaz/opt/anaconda3/envs/shoe/lib/python3.12/site-packages/rest_framework/serializers.py", line 687, in to_representation
    self.child.to_representation(item) for item in iterable
    ^^^^^^^^^^^^^^^^^^^^^^^^^^^^^^^^^^
  File "/Users/aliosmanyilmaz/opt/anaconda3/envs/shoe/lib/python3.12/site-packages/rest_framework/serializers.py", line 507, in to_representation
    for field in fields:
  File "/Users/aliosmanyilmaz/opt/anaconda3/envs/shoe/lib/python3.12/site-packages/rest_framework/serializers.py", line 368, in _readable_fields
    for field in self.fields.values():
                 ^^^^^^^^^^^
  File "/Users/aliosmanyilmaz/opt/anaconda3/envs/shoe/lib/python3.12/site-packages/django/utils/functional.py", line 57, in __get__
    res = instance.__dict__[self.name] = self.func(instance)
                                         ^^^^^^^^^^^^^^^^^^^
  File "/Users/aliosmanyilmaz/opt/anaconda3/envs/shoe/lib/python3.12/site-packages/rest_framework/serializers.py", line 357, in fields
    fields[key] = value
    ~~~~~~^^^^^
  File "/Users/aliosmanyilmaz/opt/anaconda3/envs/shoe/lib/python3.12/site-packages/rest_framework/utils/serializer_helpers.py", line 169, in __setitem__
    field.bind(field_name=key, parent=self.serializer)
  File "/Users/aliosmanyilmaz/opt/anaconda3/envs/shoe/lib/python3.12/site-packages/rest_framework/fields.py", line 367, in bind
    assert self.source != field_name, (
AssertionError: It is redundant to specify `source='image_url'` on field 'CharField' in serializer 'ProductSerializer', because it is the same as the field name. Remove the `source` keyword argument.
ERROR 2023-12-15 19:02:21,823 basehttp "GET /api/products/ HTTP/1.1" 500 135859
ERROR 2023-12-15 19:02:21,872 log Internal Server Error: /api/products/
Traceback (most recent call last):
  File "/Users/aliosmanyilmaz/opt/anaconda3/envs/shoe/lib/python3.12/site-packages/django/core/handlers/exception.py", line 55, in inner
    response = get_response(request)
               ^^^^^^^^^^^^^^^^^^^^^
  File "/Users/aliosmanyilmaz/opt/anaconda3/envs/shoe/lib/python3.12/site-packages/django/core/handlers/base.py", line 197, in _get_response
    response = wrapped_callback(request, *callback_args, **callback_kwargs)
               ^^^^^^^^^^^^^^^^^^^^^^^^^^^^^^^^^^^^^^^^^^^^^^^^^^^^^^^^^^^^
  File "/Users/aliosmanyilmaz/opt/anaconda3/envs/shoe/lib/python3.12/site-packages/sentry_sdk/integrations/django/views.py", line 84, in sentry_wrapped_callback
    return callback(request, *args, **kwargs)
           ^^^^^^^^^^^^^^^^^^^^^^^^^^^^^^^^^^
  File "/Users/aliosmanyilmaz/opt/anaconda3/envs/shoe/lib/python3.12/site-packages/django/views/decorators/csrf.py", line 56, in wrapper_view
    return view_func(*args, **kwargs)
           ^^^^^^^^^^^^^^^^^^^^^^^^^^
  File "/Users/aliosmanyilmaz/opt/anaconda3/envs/shoe/lib/python3.12/site-packages/rest_framework/viewsets.py", line 125, in view
    return self.dispatch(request, *args, **kwargs)
           ^^^^^^^^^^^^^^^^^^^^^^^^^^^^^^^^^^^^^^^
  File "/Users/aliosmanyilmaz/opt/anaconda3/envs/shoe/lib/python3.12/site-packages/rest_framework/views.py", line 509, in dispatch
    response = self.handle_exception(exc)
               ^^^^^^^^^^^^^^^^^^^^^^^^^^
  File "/Users/aliosmanyilmaz/opt/anaconda3/envs/shoe/lib/python3.12/site-packages/rest_framework/views.py", line 469, in handle_exception
    self.raise_uncaught_exception(exc)
  File "/Users/aliosmanyilmaz/opt/anaconda3/envs/shoe/lib/python3.12/site-packages/rest_framework/views.py", line 480, in raise_uncaught_exception
    raise exc
  File "/Users/aliosmanyilmaz/opt/anaconda3/envs/shoe/lib/python3.12/site-packages/rest_framework/views.py", line 506, in dispatch
    response = handler(request, *args, **kwargs)
               ^^^^^^^^^^^^^^^^^^^^^^^^^^^^^^^^^
  File "/Users/aliosmanyilmaz/opt/anaconda3/envs/shoe/lib/python3.12/site-packages/rest_framework/mixins.py", line 46, in list
    return Response(serializer.data)
                    ^^^^^^^^^^^^^^^
  File "/Users/aliosmanyilmaz/opt/anaconda3/envs/shoe/lib/python3.12/site-packages/rest_framework/serializers.py", line 768, in data
    ret = super().data
          ^^^^^^^^^^^^
  File "/Users/aliosmanyilmaz/opt/anaconda3/envs/shoe/lib/python3.12/site-packages/rest_framework/serializers.py", line 253, in data
    self._data = self.to_representation(self.instance)
                 ^^^^^^^^^^^^^^^^^^^^^^^^^^^^^^^^^^^^^
  File "/Users/aliosmanyilmaz/opt/anaconda3/envs/shoe/lib/python3.12/site-packages/rest_framework/serializers.py", line 687, in to_representation
    self.child.to_representation(item) for item in iterable
    ^^^^^^^^^^^^^^^^^^^^^^^^^^^^^^^^^^
  File "/Users/aliosmanyilmaz/opt/anaconda3/envs/shoe/lib/python3.12/site-packages/rest_framework/serializers.py", line 507, in to_representation
    for field in fields:
  File "/Users/aliosmanyilmaz/opt/anaconda3/envs/shoe/lib/python3.12/site-packages/rest_framework/serializers.py", line 368, in _readable_fields
    for field in self.fields.values():
                 ^^^^^^^^^^^
  File "/Users/aliosmanyilmaz/opt/anaconda3/envs/shoe/lib/python3.12/site-packages/django/utils/functional.py", line 57, in __get__
    res = instance.__dict__[self.name] = self.func(instance)
                                         ^^^^^^^^^^^^^^^^^^^
  File "/Users/aliosmanyilmaz/opt/anaconda3/envs/shoe/lib/python3.12/site-packages/rest_framework/serializers.py", line 357, in fields
    fields[key] = value
    ~~~~~~^^^^^
  File "/Users/aliosmanyilmaz/opt/anaconda3/envs/shoe/lib/python3.12/site-packages/rest_framework/utils/serializer_helpers.py", line 169, in __setitem__
    field.bind(field_name=key, parent=self.serializer)
  File "/Users/aliosmanyilmaz/opt/anaconda3/envs/shoe/lib/python3.12/site-packages/rest_framework/fields.py", line 367, in bind
    assert self.source != field_name, (
AssertionError: It is redundant to specify `source='image_url'` on field 'CharField' in serializer 'ProductSerializer', because it is the same as the field name. Remove the `source` keyword argument.
ERROR 2023-12-15 19:02:21,884 basehttp "GET /api/products/ HTTP/1.1" 500 135859
ERROR 2023-12-15 19:03:46,033 log Internal Server Error: /api/products/
Traceback (most recent call last):
  File "/Users/aliosmanyilmaz/opt/anaconda3/envs/shoe/lib/python3.12/site-packages/django/core/handlers/exception.py", line 55, in inner
    response = get_response(request)
               ^^^^^^^^^^^^^^^^^^^^^
  File "/Users/aliosmanyilmaz/opt/anaconda3/envs/shoe/lib/python3.12/site-packages/django/core/handlers/base.py", line 197, in _get_response
    response = wrapped_callback(request, *callback_args, **callback_kwargs)
               ^^^^^^^^^^^^^^^^^^^^^^^^^^^^^^^^^^^^^^^^^^^^^^^^^^^^^^^^^^^^
  File "/Users/aliosmanyilmaz/opt/anaconda3/envs/shoe/lib/python3.12/site-packages/sentry_sdk/integrations/django/views.py", line 84, in sentry_wrapped_callback
    return callback(request, *args, **kwargs)
           ^^^^^^^^^^^^^^^^^^^^^^^^^^^^^^^^^^
  File "/Users/aliosmanyilmaz/opt/anaconda3/envs/shoe/lib/python3.12/site-packages/django/views/decorators/csrf.py", line 56, in wrapper_view
    return view_func(*args, **kwargs)
           ^^^^^^^^^^^^^^^^^^^^^^^^^^
  File "/Users/aliosmanyilmaz/opt/anaconda3/envs/shoe/lib/python3.12/site-packages/rest_framework/viewsets.py", line 125, in view
    return self.dispatch(request, *args, **kwargs)
           ^^^^^^^^^^^^^^^^^^^^^^^^^^^^^^^^^^^^^^^
  File "/Users/aliosmanyilmaz/opt/anaconda3/envs/shoe/lib/python3.12/site-packages/rest_framework/views.py", line 509, in dispatch
    response = self.handle_exception(exc)
               ^^^^^^^^^^^^^^^^^^^^^^^^^^
  File "/Users/aliosmanyilmaz/opt/anaconda3/envs/shoe/lib/python3.12/site-packages/rest_framework/views.py", line 469, in handle_exception
    self.raise_uncaught_exception(exc)
  File "/Users/aliosmanyilmaz/opt/anaconda3/envs/shoe/lib/python3.12/site-packages/rest_framework/views.py", line 480, in raise_uncaught_exception
    raise exc
  File "/Users/aliosmanyilmaz/opt/anaconda3/envs/shoe/lib/python3.12/site-packages/rest_framework/views.py", line 506, in dispatch
    response = handler(request, *args, **kwargs)
               ^^^^^^^^^^^^^^^^^^^^^^^^^^^^^^^^^
  File "/Users/aliosmanyilmaz/opt/anaconda3/envs/shoe/lib/python3.12/site-packages/rest_framework/mixins.py", line 46, in list
    return Response(serializer.data)
                    ^^^^^^^^^^^^^^^
  File "/Users/aliosmanyilmaz/opt/anaconda3/envs/shoe/lib/python3.12/site-packages/rest_framework/serializers.py", line 768, in data
    ret = super().data
          ^^^^^^^^^^^^
  File "/Users/aliosmanyilmaz/opt/anaconda3/envs/shoe/lib/python3.12/site-packages/rest_framework/serializers.py", line 253, in data
    self._data = self.to_representation(self.instance)
                 ^^^^^^^^^^^^^^^^^^^^^^^^^^^^^^^^^^^^^
  File "/Users/aliosmanyilmaz/opt/anaconda3/envs/shoe/lib/python3.12/site-packages/rest_framework/serializers.py", line 687, in to_representation
    self.child.to_representation(item) for item in iterable
    ^^^^^^^^^^^^^^^^^^^^^^^^^^^^^^^^^^
  File "/Users/aliosmanyilmaz/opt/anaconda3/envs/shoe/lib/python3.12/site-packages/rest_framework/serializers.py", line 507, in to_representation
    for field in fields:
  File "/Users/aliosmanyilmaz/opt/anaconda3/envs/shoe/lib/python3.12/site-packages/rest_framework/serializers.py", line 368, in _readable_fields
    for field in self.fields.values():
                 ^^^^^^^^^^^
  File "/Users/aliosmanyilmaz/opt/anaconda3/envs/shoe/lib/python3.12/site-packages/django/utils/functional.py", line 57, in __get__
    res = instance.__dict__[self.name] = self.func(instance)
                                         ^^^^^^^^^^^^^^^^^^^
  File "/Users/aliosmanyilmaz/opt/anaconda3/envs/shoe/lib/python3.12/site-packages/rest_framework/serializers.py", line 357, in fields
    fields[key] = value
    ~~~~~~^^^^^
  File "/Users/aliosmanyilmaz/opt/anaconda3/envs/shoe/lib/python3.12/site-packages/rest_framework/utils/serializer_helpers.py", line 169, in __setitem__
    field.bind(field_name=key, parent=self.serializer)
  File "/Users/aliosmanyilmaz/opt/anaconda3/envs/shoe/lib/python3.12/site-packages/rest_framework/fields.py", line 367, in bind
    assert self.source != field_name, (
AssertionError: It is redundant to specify `source='image_url'` on field 'CharField' in serializer 'ProductSerializer', because it is the same as the field name. Remove the `source` keyword argument.
ERROR 2023-12-15 19:03:46,049 basehttp "GET /api/products/ HTTP/1.1" 500 136833
ERROR 2023-12-15 19:04:31,744 log Internal Server Error: /api/products/
Traceback (most recent call last):
  File "/Users/aliosmanyilmaz/opt/anaconda3/envs/shoe/lib/python3.12/site-packages/django/core/handlers/exception.py", line 55, in inner
    response = get_response(request)
               ^^^^^^^^^^^^^^^^^^^^^
  File "/Users/aliosmanyilmaz/opt/anaconda3/envs/shoe/lib/python3.12/site-packages/django/core/handlers/base.py", line 197, in _get_response
    response = wrapped_callback(request, *callback_args, **callback_kwargs)
               ^^^^^^^^^^^^^^^^^^^^^^^^^^^^^^^^^^^^^^^^^^^^^^^^^^^^^^^^^^^^
  File "/Users/aliosmanyilmaz/opt/anaconda3/envs/shoe/lib/python3.12/site-packages/sentry_sdk/integrations/django/views.py", line 84, in sentry_wrapped_callback
    return callback(request, *args, **kwargs)
           ^^^^^^^^^^^^^^^^^^^^^^^^^^^^^^^^^^
  File "/Users/aliosmanyilmaz/opt/anaconda3/envs/shoe/lib/python3.12/site-packages/django/views/decorators/csrf.py", line 56, in wrapper_view
    return view_func(*args, **kwargs)
           ^^^^^^^^^^^^^^^^^^^^^^^^^^
  File "/Users/aliosmanyilmaz/opt/anaconda3/envs/shoe/lib/python3.12/site-packages/rest_framework/viewsets.py", line 125, in view
    return self.dispatch(request, *args, **kwargs)
           ^^^^^^^^^^^^^^^^^^^^^^^^^^^^^^^^^^^^^^^
  File "/Users/aliosmanyilmaz/opt/anaconda3/envs/shoe/lib/python3.12/site-packages/rest_framework/views.py", line 509, in dispatch
    response = self.handle_exception(exc)
               ^^^^^^^^^^^^^^^^^^^^^^^^^^
  File "/Users/aliosmanyilmaz/opt/anaconda3/envs/shoe/lib/python3.12/site-packages/rest_framework/views.py", line 469, in handle_exception
    self.raise_uncaught_exception(exc)
  File "/Users/aliosmanyilmaz/opt/anaconda3/envs/shoe/lib/python3.12/site-packages/rest_framework/views.py", line 480, in raise_uncaught_exception
    raise exc
  File "/Users/aliosmanyilmaz/opt/anaconda3/envs/shoe/lib/python3.12/site-packages/rest_framework/views.py", line 506, in dispatch
    response = handler(request, *args, **kwargs)
               ^^^^^^^^^^^^^^^^^^^^^^^^^^^^^^^^^
  File "/Users/aliosmanyilmaz/opt/anaconda3/envs/shoe/lib/python3.12/site-packages/rest_framework/mixins.py", line 46, in list
    return Response(serializer.data)
                    ^^^^^^^^^^^^^^^
  File "/Users/aliosmanyilmaz/opt/anaconda3/envs/shoe/lib/python3.12/site-packages/rest_framework/serializers.py", line 768, in data
    ret = super().data
          ^^^^^^^^^^^^
  File "/Users/aliosmanyilmaz/opt/anaconda3/envs/shoe/lib/python3.12/site-packages/rest_framework/serializers.py", line 253, in data
    self._data = self.to_representation(self.instance)
                 ^^^^^^^^^^^^^^^^^^^^^^^^^^^^^^^^^^^^^
  File "/Users/aliosmanyilmaz/opt/anaconda3/envs/shoe/lib/python3.12/site-packages/rest_framework/serializers.py", line 687, in to_representation
    self.child.to_representation(item) for item in iterable
    ^^^^^^^^^^^^^^^^^^^^^^^^^^^^^^^^^^
  File "/Users/aliosmanyilmaz/opt/anaconda3/envs/shoe/lib/python3.12/site-packages/rest_framework/serializers.py", line 507, in to_representation
    for field in fields:
  File "/Users/aliosmanyilmaz/opt/anaconda3/envs/shoe/lib/python3.12/site-packages/rest_framework/serializers.py", line 368, in _readable_fields
    for field in self.fields.values():
                 ^^^^^^^^^^^
  File "/Users/aliosmanyilmaz/opt/anaconda3/envs/shoe/lib/python3.12/site-packages/django/utils/functional.py", line 57, in __get__
    res = instance.__dict__[self.name] = self.func(instance)
                                         ^^^^^^^^^^^^^^^^^^^
  File "/Users/aliosmanyilmaz/opt/anaconda3/envs/shoe/lib/python3.12/site-packages/rest_framework/serializers.py", line 357, in fields
    fields[key] = value
    ~~~~~~^^^^^
  File "/Users/aliosmanyilmaz/opt/anaconda3/envs/shoe/lib/python3.12/site-packages/rest_framework/utils/serializer_helpers.py", line 169, in __setitem__
    field.bind(field_name=key, parent=self.serializer)
  File "/Users/aliosmanyilmaz/opt/anaconda3/envs/shoe/lib/python3.12/site-packages/rest_framework/fields.py", line 367, in bind
    assert self.source != field_name, (
AssertionError: It is redundant to specify `source='image_url'` on field 'CharField' in serializer 'ProductSerializer', because it is the same as the field name. Remove the `source` keyword argument.
ERROR 2023-12-15 19:04:31,768 basehttp "GET /api/products/ HTTP/1.1" 500 135949
ERROR 2023-12-15 19:04:31,850 log Internal Server Error: /api/products/
Traceback (most recent call last):
  File "/Users/aliosmanyilmaz/opt/anaconda3/envs/shoe/lib/python3.12/site-packages/django/core/handlers/exception.py", line 55, in inner
    response = get_response(request)
               ^^^^^^^^^^^^^^^^^^^^^
  File "/Users/aliosmanyilmaz/opt/anaconda3/envs/shoe/lib/python3.12/site-packages/django/core/handlers/base.py", line 197, in _get_response
    response = wrapped_callback(request, *callback_args, **callback_kwargs)
               ^^^^^^^^^^^^^^^^^^^^^^^^^^^^^^^^^^^^^^^^^^^^^^^^^^^^^^^^^^^^
  File "/Users/aliosmanyilmaz/opt/anaconda3/envs/shoe/lib/python3.12/site-packages/sentry_sdk/integrations/django/views.py", line 84, in sentry_wrapped_callback
    return callback(request, *args, **kwargs)
           ^^^^^^^^^^^^^^^^^^^^^^^^^^^^^^^^^^
  File "/Users/aliosmanyilmaz/opt/anaconda3/envs/shoe/lib/python3.12/site-packages/django/views/decorators/csrf.py", line 56, in wrapper_view
    return view_func(*args, **kwargs)
           ^^^^^^^^^^^^^^^^^^^^^^^^^^
  File "/Users/aliosmanyilmaz/opt/anaconda3/envs/shoe/lib/python3.12/site-packages/rest_framework/viewsets.py", line 125, in view
    return self.dispatch(request, *args, **kwargs)
           ^^^^^^^^^^^^^^^^^^^^^^^^^^^^^^^^^^^^^^^
  File "/Users/aliosmanyilmaz/opt/anaconda3/envs/shoe/lib/python3.12/site-packages/rest_framework/views.py", line 509, in dispatch
    response = self.handle_exception(exc)
               ^^^^^^^^^^^^^^^^^^^^^^^^^^
  File "/Users/aliosmanyilmaz/opt/anaconda3/envs/shoe/lib/python3.12/site-packages/rest_framework/views.py", line 469, in handle_exception
    self.raise_uncaught_exception(exc)
  File "/Users/aliosmanyilmaz/opt/anaconda3/envs/shoe/lib/python3.12/site-packages/rest_framework/views.py", line 480, in raise_uncaught_exception
    raise exc
  File "/Users/aliosmanyilmaz/opt/anaconda3/envs/shoe/lib/python3.12/site-packages/rest_framework/views.py", line 506, in dispatch
    response = handler(request, *args, **kwargs)
               ^^^^^^^^^^^^^^^^^^^^^^^^^^^^^^^^^
  File "/Users/aliosmanyilmaz/opt/anaconda3/envs/shoe/lib/python3.12/site-packages/rest_framework/mixins.py", line 46, in list
    return Response(serializer.data)
                    ^^^^^^^^^^^^^^^
  File "/Users/aliosmanyilmaz/opt/anaconda3/envs/shoe/lib/python3.12/site-packages/rest_framework/serializers.py", line 768, in data
    ret = super().data
          ^^^^^^^^^^^^
  File "/Users/aliosmanyilmaz/opt/anaconda3/envs/shoe/lib/python3.12/site-packages/rest_framework/serializers.py", line 253, in data
    self._data = self.to_representation(self.instance)
                 ^^^^^^^^^^^^^^^^^^^^^^^^^^^^^^^^^^^^^
  File "/Users/aliosmanyilmaz/opt/anaconda3/envs/shoe/lib/python3.12/site-packages/rest_framework/serializers.py", line 687, in to_representation
    self.child.to_representation(item) for item in iterable
    ^^^^^^^^^^^^^^^^^^^^^^^^^^^^^^^^^^
  File "/Users/aliosmanyilmaz/opt/anaconda3/envs/shoe/lib/python3.12/site-packages/rest_framework/serializers.py", line 507, in to_representation
    for field in fields:
  File "/Users/aliosmanyilmaz/opt/anaconda3/envs/shoe/lib/python3.12/site-packages/rest_framework/serializers.py", line 368, in _readable_fields
    for field in self.fields.values():
                 ^^^^^^^^^^^
  File "/Users/aliosmanyilmaz/opt/anaconda3/envs/shoe/lib/python3.12/site-packages/django/utils/functional.py", line 57, in __get__
    res = instance.__dict__[self.name] = self.func(instance)
                                         ^^^^^^^^^^^^^^^^^^^
  File "/Users/aliosmanyilmaz/opt/anaconda3/envs/shoe/lib/python3.12/site-packages/rest_framework/serializers.py", line 357, in fields
    fields[key] = value
    ~~~~~~^^^^^
  File "/Users/aliosmanyilmaz/opt/anaconda3/envs/shoe/lib/python3.12/site-packages/rest_framework/utils/serializer_helpers.py", line 169, in __setitem__
    field.bind(field_name=key, parent=self.serializer)
  File "/Users/aliosmanyilmaz/opt/anaconda3/envs/shoe/lib/python3.12/site-packages/rest_framework/fields.py", line 367, in bind
    assert self.source != field_name, (
AssertionError: It is redundant to specify `source='image_url'` on field 'CharField' in serializer 'ProductSerializer', because it is the same as the field name. Remove the `source` keyword argument.
ERROR 2023-12-15 19:04:31,868 basehttp "GET /api/products/ HTTP/1.1" 500 135949
ERROR 2023-12-15 19:04:41,905 log Internal Server Error: /api/products/
Traceback (most recent call last):
  File "/Users/aliosmanyilmaz/opt/anaconda3/envs/shoe/lib/python3.12/site-packages/django/core/handlers/exception.py", line 55, in inner
    response = get_response(request)
               ^^^^^^^^^^^^^^^^^^^^^
  File "/Users/aliosmanyilmaz/opt/anaconda3/envs/shoe/lib/python3.12/site-packages/django/core/handlers/base.py", line 197, in _get_response
    response = wrapped_callback(request, *callback_args, **callback_kwargs)
               ^^^^^^^^^^^^^^^^^^^^^^^^^^^^^^^^^^^^^^^^^^^^^^^^^^^^^^^^^^^^
  File "/Users/aliosmanyilmaz/opt/anaconda3/envs/shoe/lib/python3.12/site-packages/sentry_sdk/integrations/django/views.py", line 84, in sentry_wrapped_callback
    return callback(request, *args, **kwargs)
           ^^^^^^^^^^^^^^^^^^^^^^^^^^^^^^^^^^
  File "/Users/aliosmanyilmaz/opt/anaconda3/envs/shoe/lib/python3.12/site-packages/django/views/decorators/csrf.py", line 56, in wrapper_view
    return view_func(*args, **kwargs)
           ^^^^^^^^^^^^^^^^^^^^^^^^^^
  File "/Users/aliosmanyilmaz/opt/anaconda3/envs/shoe/lib/python3.12/site-packages/rest_framework/viewsets.py", line 125, in view
    return self.dispatch(request, *args, **kwargs)
           ^^^^^^^^^^^^^^^^^^^^^^^^^^^^^^^^^^^^^^^
  File "/Users/aliosmanyilmaz/opt/anaconda3/envs/shoe/lib/python3.12/site-packages/rest_framework/views.py", line 509, in dispatch
    response = self.handle_exception(exc)
               ^^^^^^^^^^^^^^^^^^^^^^^^^^
  File "/Users/aliosmanyilmaz/opt/anaconda3/envs/shoe/lib/python3.12/site-packages/rest_framework/views.py", line 469, in handle_exception
    self.raise_uncaught_exception(exc)
  File "/Users/aliosmanyilmaz/opt/anaconda3/envs/shoe/lib/python3.12/site-packages/rest_framework/views.py", line 480, in raise_uncaught_exception
    raise exc
  File "/Users/aliosmanyilmaz/opt/anaconda3/envs/shoe/lib/python3.12/site-packages/rest_framework/views.py", line 506, in dispatch
    response = handler(request, *args, **kwargs)
               ^^^^^^^^^^^^^^^^^^^^^^^^^^^^^^^^^
  File "/Users/aliosmanyilmaz/opt/anaconda3/envs/shoe/lib/python3.12/site-packages/rest_framework/mixins.py", line 46, in list
    return Response(serializer.data)
                    ^^^^^^^^^^^^^^^
  File "/Users/aliosmanyilmaz/opt/anaconda3/envs/shoe/lib/python3.12/site-packages/rest_framework/serializers.py", line 768, in data
    ret = super().data
          ^^^^^^^^^^^^
  File "/Users/aliosmanyilmaz/opt/anaconda3/envs/shoe/lib/python3.12/site-packages/rest_framework/serializers.py", line 253, in data
    self._data = self.to_representation(self.instance)
                 ^^^^^^^^^^^^^^^^^^^^^^^^^^^^^^^^^^^^^
  File "/Users/aliosmanyilmaz/opt/anaconda3/envs/shoe/lib/python3.12/site-packages/rest_framework/serializers.py", line 687, in to_representation
    self.child.to_representation(item) for item in iterable
    ^^^^^^^^^^^^^^^^^^^^^^^^^^^^^^^^^^
  File "/Users/aliosmanyilmaz/opt/anaconda3/envs/shoe/lib/python3.12/site-packages/rest_framework/serializers.py", line 507, in to_representation
    for field in fields:
  File "/Users/aliosmanyilmaz/opt/anaconda3/envs/shoe/lib/python3.12/site-packages/rest_framework/serializers.py", line 368, in _readable_fields
    for field in self.fields.values():
                 ^^^^^^^^^^^
  File "/Users/aliosmanyilmaz/opt/anaconda3/envs/shoe/lib/python3.12/site-packages/django/utils/functional.py", line 57, in __get__
    res = instance.__dict__[self.name] = self.func(instance)
                                         ^^^^^^^^^^^^^^^^^^^
  File "/Users/aliosmanyilmaz/opt/anaconda3/envs/shoe/lib/python3.12/site-packages/rest_framework/serializers.py", line 357, in fields
    fields[key] = value
    ~~~~~~^^^^^
  File "/Users/aliosmanyilmaz/opt/anaconda3/envs/shoe/lib/python3.12/site-packages/rest_framework/utils/serializer_helpers.py", line 169, in __setitem__
    field.bind(field_name=key, parent=self.serializer)
  File "/Users/aliosmanyilmaz/opt/anaconda3/envs/shoe/lib/python3.12/site-packages/rest_framework/fields.py", line 367, in bind
    assert self.source != field_name, (
AssertionError: It is redundant to specify `source='image_url'` on field 'CharField' in serializer 'ProductSerializer', because it is the same as the field name. Remove the `source` keyword argument.
ERROR 2023-12-15 19:04:41,934 basehttp "GET /api/products/ HTTP/1.1" 500 137060
ERROR 2023-12-16 12:34:58,677 log Internal Server Error: /admin/api/category/
Traceback (most recent call last):
  File "/Users/aliosmanyilmaz/opt/anaconda3/envs/shoe/lib/python3.12/site-packages/django/db/backends/utils.py", line 89, in _execute
    return self.cursor.execute(sql, params)
           ^^^^^^^^^^^^^^^^^^^^^^^^^^^^^^^^
  File "/Users/aliosmanyilmaz/opt/anaconda3/envs/shoe/lib/python3.12/site-packages/django/db/backends/sqlite3/base.py", line 328, in execute
    return super().execute(query, params)
           ^^^^^^^^^^^^^^^^^^^^^^^^^^^^^^
sqlite3.OperationalError: no such column: api_category.image

The above exception was the direct cause of the following exception:

Traceback (most recent call last):
  File "/Users/aliosmanyilmaz/opt/anaconda3/envs/shoe/lib/python3.12/site-packages/silk/sql.py", line 89, in execute_sql
    return self._execute_sql(*args, **kwargs)
           ^^^^^^^^^^^^^^^^^^^^^^^^^^^^^^^^^^
  File "/Users/aliosmanyilmaz/opt/anaconda3/envs/shoe/lib/python3.12/site-packages/django/db/models/sql/compiler.py", line 1562, in execute_sql
    cursor.execute(sql, params)
  File "/Users/aliosmanyilmaz/opt/anaconda3/envs/shoe/lib/python3.12/site-packages/django/db/backends/utils.py", line 102, in execute
    return super().execute(sql, params)
           ^^^^^^^^^^^^^^^^^^^^^^^^^^^^
  File "/Users/aliosmanyilmaz/opt/anaconda3/envs/shoe/lib/python3.12/site-packages/sentry_sdk/integrations/django/__init__.py", line 641, in execute
    result = real_execute(self, sql, params)
             ^^^^^^^^^^^^^^^^^^^^^^^^^^^^^^^
  File "/Users/aliosmanyilmaz/opt/anaconda3/envs/shoe/lib/python3.12/site-packages/django/db/backends/utils.py", line 67, in execute
    return self._execute_with_wrappers(
           ^^^^^^^^^^^^^^^^^^^^^^^^^^^^
  File "/Users/aliosmanyilmaz/opt/anaconda3/envs/shoe/lib/python3.12/site-packages/django/db/backends/utils.py", line 80, in _execute_with_wrappers
    return executor(sql, params, many, context)
           ^^^^^^^^^^^^^^^^^^^^^^^^^^^^^^^^^^^^
  File "/Users/aliosmanyilmaz/opt/anaconda3/envs/shoe/lib/python3.12/site-packages/django/db/backends/utils.py", line 84, in _execute
    with self.db.wrap_database_errors:
  File "/Users/aliosmanyilmaz/opt/anaconda3/envs/shoe/lib/python3.12/site-packages/django/db/utils.py", line 91, in __exit__
    raise dj_exc_value.with_traceback(traceback) from exc_value
  File "/Users/aliosmanyilmaz/opt/anaconda3/envs/shoe/lib/python3.12/site-packages/django/db/backends/utils.py", line 89, in _execute
    return self.cursor.execute(sql, params)
           ^^^^^^^^^^^^^^^^^^^^^^^^^^^^^^^^
  File "/Users/aliosmanyilmaz/opt/anaconda3/envs/shoe/lib/python3.12/site-packages/django/db/backends/sqlite3/base.py", line 328, in execute
    return super().execute(query, params)
           ^^^^^^^^^^^^^^^^^^^^^^^^^^^^^^
django.db.utils.OperationalError: no such column: api_category.image

During handling of the above exception, another exception occurred:

Traceback (most recent call last):
  File "/Users/aliosmanyilmaz/opt/anaconda3/envs/shoe/lib/python3.12/site-packages/django/db/backends/utils.py", line 89, in _execute
    return self.cursor.execute(sql, params)
           ^^^^^^^^^^^^^^^^^^^^^^^^^^^^^^^^
  File "/Users/aliosmanyilmaz/opt/anaconda3/envs/shoe/lib/python3.12/site-packages/django/db/backends/sqlite3/base.py", line 328, in execute
    return super().execute(query, params)
           ^^^^^^^^^^^^^^^^^^^^^^^^^^^^^^
sqlite3.OperationalError: no such column: api_category.image

The above exception was the direct cause of the following exception:

Traceback (most recent call last):
  File "/Users/aliosmanyilmaz/opt/anaconda3/envs/shoe/lib/python3.12/site-packages/django/core/handlers/exception.py", line 55, in inner
    response = get_response(request)
               ^^^^^^^^^^^^^^^^^^^^^
  File "/Users/aliosmanyilmaz/opt/anaconda3/envs/shoe/lib/python3.12/site-packages/django/core/handlers/base.py", line 197, in _get_response
    response = wrapped_callback(request, *callback_args, **callback_kwargs)
               ^^^^^^^^^^^^^^^^^^^^^^^^^^^^^^^^^^^^^^^^^^^^^^^^^^^^^^^^^^^^
  File "/Users/aliosmanyilmaz/opt/anaconda3/envs/shoe/lib/python3.12/site-packages/sentry_sdk/integrations/django/views.py", line 84, in sentry_wrapped_callback
    return callback(request, *args, **kwargs)
           ^^^^^^^^^^^^^^^^^^^^^^^^^^^^^^^^^^
  File "/Users/aliosmanyilmaz/opt/anaconda3/envs/shoe/lib/python3.12/site-packages/django/contrib/admin/options.py", line 688, in wrapper
    return self.admin_site.admin_view(view)(*args, **kwargs)
           ^^^^^^^^^^^^^^^^^^^^^^^^^^^^^^^^^^^^^^^^^^^^^^^^^
  File "/Users/aliosmanyilmaz/opt/anaconda3/envs/shoe/lib/python3.12/site-packages/django/utils/decorators.py", line 134, in _wrapper_view
    response = view_func(request, *args, **kwargs)
               ^^^^^^^^^^^^^^^^^^^^^^^^^^^^^^^^^^^
  File "/Users/aliosmanyilmaz/opt/anaconda3/envs/shoe/lib/python3.12/site-packages/django/views/decorators/cache.py", line 62, in _wrapper_view_func
    response = view_func(request, *args, **kwargs)
               ^^^^^^^^^^^^^^^^^^^^^^^^^^^^^^^^^^^
  File "/Users/aliosmanyilmaz/opt/anaconda3/envs/shoe/lib/python3.12/site-packages/django/contrib/admin/sites.py", line 242, in inner
    return view(request, *args, **kwargs)
           ^^^^^^^^^^^^^^^^^^^^^^^^^^^^^^
  File "/Users/aliosmanyilmaz/opt/anaconda3/envs/shoe/lib/python3.12/site-packages/django/utils/decorators.py", line 46, in _wrapper
    return bound_method(*args, **kwargs)
           ^^^^^^^^^^^^^^^^^^^^^^^^^^^^^
  File "/Users/aliosmanyilmaz/opt/anaconda3/envs/shoe/lib/python3.12/site-packages/django/utils/decorators.py", line 134, in _wrapper_view
    response = view_func(request, *args, **kwargs)
               ^^^^^^^^^^^^^^^^^^^^^^^^^^^^^^^^^^^
  File "/Users/aliosmanyilmaz/opt/anaconda3/envs/shoe/lib/python3.12/site-packages/django/contrib/admin/options.py", line 2065, in changelist_view
    "selection_note": _("0 of %(cnt)s selected") % {"cnt": len(cl.result_list)},
                                                           ^^^^^^^^^^^^^^^^^^^
  File "/Users/aliosmanyilmaz/opt/anaconda3/envs/shoe/lib/python3.12/site-packages/django/db/models/query.py", line 380, in __len__
    self._fetch_all()
  File "/Users/aliosmanyilmaz/opt/anaconda3/envs/shoe/lib/python3.12/site-packages/django/db/models/query.py", line 1881, in _fetch_all
    self._result_cache = list(self._iterable_class(self))
                         ^^^^^^^^^^^^^^^^^^^^^^^^^^^^^^^^
  File "/Users/aliosmanyilmaz/opt/anaconda3/envs/shoe/lib/python3.12/site-packages/django/db/models/query.py", line 91, in __iter__
    results = compiler.execute_sql(
              ^^^^^^^^^^^^^^^^^^^^^
  File "/Users/aliosmanyilmaz/opt/anaconda3/envs/shoe/lib/python3.12/site-packages/silk/sql.py", line 96, in execute_sql
    query_dict['analysis'] = _explain_query(self.connection, q, params)
                             ^^^^^^^^^^^^^^^^^^^^^^^^^^^^^^^^^^^^^^^^^^
  File "/Users/aliosmanyilmaz/opt/anaconda3/envs/shoe/lib/python3.12/site-packages/silk/sql.py", line 58, in _explain_query
    cur.execute(prefixed_query, params)
  File "/Users/aliosmanyilmaz/opt/anaconda3/envs/shoe/lib/python3.12/site-packages/django/db/backends/utils.py", line 102, in execute
    return super().execute(sql, params)
           ^^^^^^^^^^^^^^^^^^^^^^^^^^^^
  File "/Users/aliosmanyilmaz/opt/anaconda3/envs/shoe/lib/python3.12/site-packages/sentry_sdk/integrations/django/__init__.py", line 641, in execute
    result = real_execute(self, sql, params)
             ^^^^^^^^^^^^^^^^^^^^^^^^^^^^^^^
  File "/Users/aliosmanyilmaz/opt/anaconda3/envs/shoe/lib/python3.12/site-packages/django/db/backends/utils.py", line 67, in execute
    return self._execute_with_wrappers(
           ^^^^^^^^^^^^^^^^^^^^^^^^^^^^
  File "/Users/aliosmanyilmaz/opt/anaconda3/envs/shoe/lib/python3.12/site-packages/django/db/backends/utils.py", line 80, in _execute_with_wrappers
    return executor(sql, params, many, context)
           ^^^^^^^^^^^^^^^^^^^^^^^^^^^^^^^^^^^^
  File "/Users/aliosmanyilmaz/opt/anaconda3/envs/shoe/lib/python3.12/site-packages/django/db/backends/utils.py", line 84, in _execute
    with self.db.wrap_database_errors:
  File "/Users/aliosmanyilmaz/opt/anaconda3/envs/shoe/lib/python3.12/site-packages/django/db/utils.py", line 91, in __exit__
    raise dj_exc_value.with_traceback(traceback) from exc_value
  File "/Users/aliosmanyilmaz/opt/anaconda3/envs/shoe/lib/python3.12/site-packages/django/db/backends/utils.py", line 89, in _execute
    return self.cursor.execute(sql, params)
           ^^^^^^^^^^^^^^^^^^^^^^^^^^^^^^^^
  File "/Users/aliosmanyilmaz/opt/anaconda3/envs/shoe/lib/python3.12/site-packages/django/db/backends/sqlite3/base.py", line 328, in execute
    return super().execute(query, params)
           ^^^^^^^^^^^^^^^^^^^^^^^^^^^^^^
django.db.utils.OperationalError: no such column: api_category.image
ERROR 2023-12-16 12:34:58,703 basehttp "GET /admin/api/category/ HTTP/1.1" 500 254779
ERROR 2023-12-16 12:35:05,479 log Internal Server Error: /admin/api/category/
Traceback (most recent call last):
  File "/Users/aliosmanyilmaz/opt/anaconda3/envs/shoe/lib/python3.12/site-packages/django/db/backends/utils.py", line 89, in _execute
    return self.cursor.execute(sql, params)
           ^^^^^^^^^^^^^^^^^^^^^^^^^^^^^^^^
  File "/Users/aliosmanyilmaz/opt/anaconda3/envs/shoe/lib/python3.12/site-packages/django/db/backends/sqlite3/base.py", line 328, in execute
    return super().execute(query, params)
           ^^^^^^^^^^^^^^^^^^^^^^^^^^^^^^
sqlite3.OperationalError: no such column: api_category.image

The above exception was the direct cause of the following exception:

Traceback (most recent call last):
  File "/Users/aliosmanyilmaz/opt/anaconda3/envs/shoe/lib/python3.12/site-packages/silk/sql.py", line 89, in execute_sql
    return self._execute_sql(*args, **kwargs)
           ^^^^^^^^^^^^^^^^^^^^^^^^^^^^^^^^^^
  File "/Users/aliosmanyilmaz/opt/anaconda3/envs/shoe/lib/python3.12/site-packages/django/db/models/sql/compiler.py", line 1562, in execute_sql
    cursor.execute(sql, params)
  File "/Users/aliosmanyilmaz/opt/anaconda3/envs/shoe/lib/python3.12/site-packages/django/db/backends/utils.py", line 102, in execute
    return super().execute(sql, params)
           ^^^^^^^^^^^^^^^^^^^^^^^^^^^^
  File "/Users/aliosmanyilmaz/opt/anaconda3/envs/shoe/lib/python3.12/site-packages/sentry_sdk/integrations/django/__init__.py", line 641, in execute
    result = real_execute(self, sql, params)
             ^^^^^^^^^^^^^^^^^^^^^^^^^^^^^^^
  File "/Users/aliosmanyilmaz/opt/anaconda3/envs/shoe/lib/python3.12/site-packages/django/db/backends/utils.py", line 67, in execute
    return self._execute_with_wrappers(
           ^^^^^^^^^^^^^^^^^^^^^^^^^^^^
  File "/Users/aliosmanyilmaz/opt/anaconda3/envs/shoe/lib/python3.12/site-packages/django/db/backends/utils.py", line 80, in _execute_with_wrappers
    return executor(sql, params, many, context)
           ^^^^^^^^^^^^^^^^^^^^^^^^^^^^^^^^^^^^
  File "/Users/aliosmanyilmaz/opt/anaconda3/envs/shoe/lib/python3.12/site-packages/django/db/backends/utils.py", line 84, in _execute
    with self.db.wrap_database_errors:
  File "/Users/aliosmanyilmaz/opt/anaconda3/envs/shoe/lib/python3.12/site-packages/django/db/utils.py", line 91, in __exit__
    raise dj_exc_value.with_traceback(traceback) from exc_value
  File "/Users/aliosmanyilmaz/opt/anaconda3/envs/shoe/lib/python3.12/site-packages/django/db/backends/utils.py", line 89, in _execute
    return self.cursor.execute(sql, params)
           ^^^^^^^^^^^^^^^^^^^^^^^^^^^^^^^^
  File "/Users/aliosmanyilmaz/opt/anaconda3/envs/shoe/lib/python3.12/site-packages/django/db/backends/sqlite3/base.py", line 328, in execute
    return super().execute(query, params)
           ^^^^^^^^^^^^^^^^^^^^^^^^^^^^^^
django.db.utils.OperationalError: no such column: api_category.image

During handling of the above exception, another exception occurred:

Traceback (most recent call last):
  File "/Users/aliosmanyilmaz/opt/anaconda3/envs/shoe/lib/python3.12/site-packages/django/db/backends/utils.py", line 89, in _execute
    return self.cursor.execute(sql, params)
           ^^^^^^^^^^^^^^^^^^^^^^^^^^^^^^^^
  File "/Users/aliosmanyilmaz/opt/anaconda3/envs/shoe/lib/python3.12/site-packages/django/db/backends/sqlite3/base.py", line 328, in execute
    return super().execute(query, params)
           ^^^^^^^^^^^^^^^^^^^^^^^^^^^^^^
sqlite3.OperationalError: no such column: api_category.image

The above exception was the direct cause of the following exception:

Traceback (most recent call last):
  File "/Users/aliosmanyilmaz/opt/anaconda3/envs/shoe/lib/python3.12/site-packages/django/core/handlers/exception.py", line 55, in inner
    response = get_response(request)
               ^^^^^^^^^^^^^^^^^^^^^
  File "/Users/aliosmanyilmaz/opt/anaconda3/envs/shoe/lib/python3.12/site-packages/django/core/handlers/base.py", line 197, in _get_response
    response = wrapped_callback(request, *callback_args, **callback_kwargs)
               ^^^^^^^^^^^^^^^^^^^^^^^^^^^^^^^^^^^^^^^^^^^^^^^^^^^^^^^^^^^^
  File "/Users/aliosmanyilmaz/opt/anaconda3/envs/shoe/lib/python3.12/site-packages/sentry_sdk/integrations/django/views.py", line 84, in sentry_wrapped_callback
    return callback(request, *args, **kwargs)
           ^^^^^^^^^^^^^^^^^^^^^^^^^^^^^^^^^^
  File "/Users/aliosmanyilmaz/opt/anaconda3/envs/shoe/lib/python3.12/site-packages/django/contrib/admin/options.py", line 688, in wrapper
    return self.admin_site.admin_view(view)(*args, **kwargs)
           ^^^^^^^^^^^^^^^^^^^^^^^^^^^^^^^^^^^^^^^^^^^^^^^^^
  File "/Users/aliosmanyilmaz/opt/anaconda3/envs/shoe/lib/python3.12/site-packages/django/utils/decorators.py", line 134, in _wrapper_view
    response = view_func(request, *args, **kwargs)
               ^^^^^^^^^^^^^^^^^^^^^^^^^^^^^^^^^^^
  File "/Users/aliosmanyilmaz/opt/anaconda3/envs/shoe/lib/python3.12/site-packages/django/views/decorators/cache.py", line 62, in _wrapper_view_func
    response = view_func(request, *args, **kwargs)
               ^^^^^^^^^^^^^^^^^^^^^^^^^^^^^^^^^^^
  File "/Users/aliosmanyilmaz/opt/anaconda3/envs/shoe/lib/python3.12/site-packages/django/contrib/admin/sites.py", line 242, in inner
    return view(request, *args, **kwargs)
           ^^^^^^^^^^^^^^^^^^^^^^^^^^^^^^
  File "/Users/aliosmanyilmaz/opt/anaconda3/envs/shoe/lib/python3.12/site-packages/django/utils/decorators.py", line 46, in _wrapper
    return bound_method(*args, **kwargs)
           ^^^^^^^^^^^^^^^^^^^^^^^^^^^^^
  File "/Users/aliosmanyilmaz/opt/anaconda3/envs/shoe/lib/python3.12/site-packages/django/utils/decorators.py", line 134, in _wrapper_view
    response = view_func(request, *args, **kwargs)
               ^^^^^^^^^^^^^^^^^^^^^^^^^^^^^^^^^^^
  File "/Users/aliosmanyilmaz/opt/anaconda3/envs/shoe/lib/python3.12/site-packages/django/contrib/admin/options.py", line 2065, in changelist_view
    "selection_note": _("0 of %(cnt)s selected") % {"cnt": len(cl.result_list)},
                                                           ^^^^^^^^^^^^^^^^^^^
  File "/Users/aliosmanyilmaz/opt/anaconda3/envs/shoe/lib/python3.12/site-packages/django/db/models/query.py", line 380, in __len__
    self._fetch_all()
  File "/Users/aliosmanyilmaz/opt/anaconda3/envs/shoe/lib/python3.12/site-packages/django/db/models/query.py", line 1881, in _fetch_all
    self._result_cache = list(self._iterable_class(self))
                         ^^^^^^^^^^^^^^^^^^^^^^^^^^^^^^^^
  File "/Users/aliosmanyilmaz/opt/anaconda3/envs/shoe/lib/python3.12/site-packages/django/db/models/query.py", line 91, in __iter__
    results = compiler.execute_sql(
              ^^^^^^^^^^^^^^^^^^^^^
  File "/Users/aliosmanyilmaz/opt/anaconda3/envs/shoe/lib/python3.12/site-packages/silk/sql.py", line 96, in execute_sql
    query_dict['analysis'] = _explain_query(self.connection, q, params)
                             ^^^^^^^^^^^^^^^^^^^^^^^^^^^^^^^^^^^^^^^^^^
  File "/Users/aliosmanyilmaz/opt/anaconda3/envs/shoe/lib/python3.12/site-packages/silk/sql.py", line 58, in _explain_query
    cur.execute(prefixed_query, params)
  File "/Users/aliosmanyilmaz/opt/anaconda3/envs/shoe/lib/python3.12/site-packages/django/db/backends/utils.py", line 102, in execute
    return super().execute(sql, params)
           ^^^^^^^^^^^^^^^^^^^^^^^^^^^^
  File "/Users/aliosmanyilmaz/opt/anaconda3/envs/shoe/lib/python3.12/site-packages/sentry_sdk/integrations/django/__init__.py", line 641, in execute
    result = real_execute(self, sql, params)
             ^^^^^^^^^^^^^^^^^^^^^^^^^^^^^^^
  File "/Users/aliosmanyilmaz/opt/anaconda3/envs/shoe/lib/python3.12/site-packages/django/db/backends/utils.py", line 67, in execute
    return self._execute_with_wrappers(
           ^^^^^^^^^^^^^^^^^^^^^^^^^^^^
  File "/Users/aliosmanyilmaz/opt/anaconda3/envs/shoe/lib/python3.12/site-packages/django/db/backends/utils.py", line 80, in _execute_with_wrappers
    return executor(sql, params, many, context)
           ^^^^^^^^^^^^^^^^^^^^^^^^^^^^^^^^^^^^
  File "/Users/aliosmanyilmaz/opt/anaconda3/envs/shoe/lib/python3.12/site-packages/django/db/backends/utils.py", line 84, in _execute
    with self.db.wrap_database_errors:
  File "/Users/aliosmanyilmaz/opt/anaconda3/envs/shoe/lib/python3.12/site-packages/django/db/utils.py", line 91, in __exit__
    raise dj_exc_value.with_traceback(traceback) from exc_value
  File "/Users/aliosmanyilmaz/opt/anaconda3/envs/shoe/lib/python3.12/site-packages/django/db/backends/utils.py", line 89, in _execute
    return self.cursor.execute(sql, params)
           ^^^^^^^^^^^^^^^^^^^^^^^^^^^^^^^^
  File "/Users/aliosmanyilmaz/opt/anaconda3/envs/shoe/lib/python3.12/site-packages/django/db/backends/sqlite3/base.py", line 328, in execute
    return super().execute(query, params)
           ^^^^^^^^^^^^^^^^^^^^^^^^^^^^^^
django.db.utils.OperationalError: no such column: api_category.image
ERROR 2023-12-16 12:35:05,498 basehttp "GET /admin/api/category/ HTTP/1.1" 500 254634
ERROR 2023-12-16 12:36:46,482 log Internal Server Error: /admin/api/category/
Traceback (most recent call last):
  File "/Users/aliosmanyilmaz/opt/anaconda3/envs/shoe/lib/python3.12/site-packages/django/db/backends/utils.py", line 89, in _execute
    return self.cursor.execute(sql, params)
           ^^^^^^^^^^^^^^^^^^^^^^^^^^^^^^^^
  File "/Users/aliosmanyilmaz/opt/anaconda3/envs/shoe/lib/python3.12/site-packages/django/db/backends/sqlite3/base.py", line 328, in execute
    return super().execute(query, params)
           ^^^^^^^^^^^^^^^^^^^^^^^^^^^^^^
sqlite3.OperationalError: no such column: api_category.image

The above exception was the direct cause of the following exception:

Traceback (most recent call last):
  File "/Users/aliosmanyilmaz/opt/anaconda3/envs/shoe/lib/python3.12/site-packages/silk/sql.py", line 89, in execute_sql
    return self._execute_sql(*args, **kwargs)
           ^^^^^^^^^^^^^^^^^^^^^^^^^^^^^^^^^^
  File "/Users/aliosmanyilmaz/opt/anaconda3/envs/shoe/lib/python3.12/site-packages/django/db/models/sql/compiler.py", line 1562, in execute_sql
    cursor.execute(sql, params)
  File "/Users/aliosmanyilmaz/opt/anaconda3/envs/shoe/lib/python3.12/site-packages/django/db/backends/utils.py", line 102, in execute
    return super().execute(sql, params)
           ^^^^^^^^^^^^^^^^^^^^^^^^^^^^
  File "/Users/aliosmanyilmaz/opt/anaconda3/envs/shoe/lib/python3.12/site-packages/sentry_sdk/integrations/django/__init__.py", line 641, in execute
    result = real_execute(self, sql, params)
             ^^^^^^^^^^^^^^^^^^^^^^^^^^^^^^^
  File "/Users/aliosmanyilmaz/opt/anaconda3/envs/shoe/lib/python3.12/site-packages/django/db/backends/utils.py", line 67, in execute
    return self._execute_with_wrappers(
           ^^^^^^^^^^^^^^^^^^^^^^^^^^^^
  File "/Users/aliosmanyilmaz/opt/anaconda3/envs/shoe/lib/python3.12/site-packages/django/db/backends/utils.py", line 80, in _execute_with_wrappers
    return executor(sql, params, many, context)
           ^^^^^^^^^^^^^^^^^^^^^^^^^^^^^^^^^^^^
  File "/Users/aliosmanyilmaz/opt/anaconda3/envs/shoe/lib/python3.12/site-packages/django/db/backends/utils.py", line 84, in _execute
    with self.db.wrap_database_errors:
  File "/Users/aliosmanyilmaz/opt/anaconda3/envs/shoe/lib/python3.12/site-packages/django/db/utils.py", line 91, in __exit__
    raise dj_exc_value.with_traceback(traceback) from exc_value
  File "/Users/aliosmanyilmaz/opt/anaconda3/envs/shoe/lib/python3.12/site-packages/django/db/backends/utils.py", line 89, in _execute
    return self.cursor.execute(sql, params)
           ^^^^^^^^^^^^^^^^^^^^^^^^^^^^^^^^
  File "/Users/aliosmanyilmaz/opt/anaconda3/envs/shoe/lib/python3.12/site-packages/django/db/backends/sqlite3/base.py", line 328, in execute
    return super().execute(query, params)
           ^^^^^^^^^^^^^^^^^^^^^^^^^^^^^^
django.db.utils.OperationalError: no such column: api_category.image

During handling of the above exception, another exception occurred:

Traceback (most recent call last):
  File "/Users/aliosmanyilmaz/opt/anaconda3/envs/shoe/lib/python3.12/site-packages/django/db/backends/utils.py", line 89, in _execute
    return self.cursor.execute(sql, params)
           ^^^^^^^^^^^^^^^^^^^^^^^^^^^^^^^^
  File "/Users/aliosmanyilmaz/opt/anaconda3/envs/shoe/lib/python3.12/site-packages/django/db/backends/sqlite3/base.py", line 328, in execute
    return super().execute(query, params)
           ^^^^^^^^^^^^^^^^^^^^^^^^^^^^^^
sqlite3.OperationalError: no such column: api_category.image

The above exception was the direct cause of the following exception:

Traceback (most recent call last):
  File "/Users/aliosmanyilmaz/opt/anaconda3/envs/shoe/lib/python3.12/site-packages/django/core/handlers/exception.py", line 55, in inner
    response = get_response(request)
               ^^^^^^^^^^^^^^^^^^^^^
  File "/Users/aliosmanyilmaz/opt/anaconda3/envs/shoe/lib/python3.12/site-packages/django/core/handlers/base.py", line 197, in _get_response
    response = wrapped_callback(request, *callback_args, **callback_kwargs)
               ^^^^^^^^^^^^^^^^^^^^^^^^^^^^^^^^^^^^^^^^^^^^^^^^^^^^^^^^^^^^
  File "/Users/aliosmanyilmaz/opt/anaconda3/envs/shoe/lib/python3.12/site-packages/sentry_sdk/integrations/django/views.py", line 84, in sentry_wrapped_callback
    return callback(request, *args, **kwargs)
           ^^^^^^^^^^^^^^^^^^^^^^^^^^^^^^^^^^
  File "/Users/aliosmanyilmaz/opt/anaconda3/envs/shoe/lib/python3.12/site-packages/django/contrib/admin/options.py", line 688, in wrapper
    return self.admin_site.admin_view(view)(*args, **kwargs)
           ^^^^^^^^^^^^^^^^^^^^^^^^^^^^^^^^^^^^^^^^^^^^^^^^^
  File "/Users/aliosmanyilmaz/opt/anaconda3/envs/shoe/lib/python3.12/site-packages/django/utils/decorators.py", line 134, in _wrapper_view
    response = view_func(request, *args, **kwargs)
               ^^^^^^^^^^^^^^^^^^^^^^^^^^^^^^^^^^^
  File "/Users/aliosmanyilmaz/opt/anaconda3/envs/shoe/lib/python3.12/site-packages/django/views/decorators/cache.py", line 62, in _wrapper_view_func
    response = view_func(request, *args, **kwargs)
               ^^^^^^^^^^^^^^^^^^^^^^^^^^^^^^^^^^^
  File "/Users/aliosmanyilmaz/opt/anaconda3/envs/shoe/lib/python3.12/site-packages/django/contrib/admin/sites.py", line 242, in inner
    return view(request, *args, **kwargs)
           ^^^^^^^^^^^^^^^^^^^^^^^^^^^^^^
  File "/Users/aliosmanyilmaz/opt/anaconda3/envs/shoe/lib/python3.12/site-packages/django/utils/decorators.py", line 46, in _wrapper
    return bound_method(*args, **kwargs)
           ^^^^^^^^^^^^^^^^^^^^^^^^^^^^^
  File "/Users/aliosmanyilmaz/opt/anaconda3/envs/shoe/lib/python3.12/site-packages/django/utils/decorators.py", line 134, in _wrapper_view
    response = view_func(request, *args, **kwargs)
               ^^^^^^^^^^^^^^^^^^^^^^^^^^^^^^^^^^^
  File "/Users/aliosmanyilmaz/opt/anaconda3/envs/shoe/lib/python3.12/site-packages/django/contrib/admin/options.py", line 2065, in changelist_view
    "selection_note": _("0 of %(cnt)s selected") % {"cnt": len(cl.result_list)},
                                                           ^^^^^^^^^^^^^^^^^^^
  File "/Users/aliosmanyilmaz/opt/anaconda3/envs/shoe/lib/python3.12/site-packages/django/db/models/query.py", line 380, in __len__
    self._fetch_all()
  File "/Users/aliosmanyilmaz/opt/anaconda3/envs/shoe/lib/python3.12/site-packages/django/db/models/query.py", line 1881, in _fetch_all
    self._result_cache = list(self._iterable_class(self))
                         ^^^^^^^^^^^^^^^^^^^^^^^^^^^^^^^^
  File "/Users/aliosmanyilmaz/opt/anaconda3/envs/shoe/lib/python3.12/site-packages/django/db/models/query.py", line 91, in __iter__
    results = compiler.execute_sql(
              ^^^^^^^^^^^^^^^^^^^^^
  File "/Users/aliosmanyilmaz/opt/anaconda3/envs/shoe/lib/python3.12/site-packages/silk/sql.py", line 96, in execute_sql
    query_dict['analysis'] = _explain_query(self.connection, q, params)
                             ^^^^^^^^^^^^^^^^^^^^^^^^^^^^^^^^^^^^^^^^^^
  File "/Users/aliosmanyilmaz/opt/anaconda3/envs/shoe/lib/python3.12/site-packages/silk/sql.py", line 58, in _explain_query
    cur.execute(prefixed_query, params)
  File "/Users/aliosmanyilmaz/opt/anaconda3/envs/shoe/lib/python3.12/site-packages/django/db/backends/utils.py", line 102, in execute
    return super().execute(sql, params)
           ^^^^^^^^^^^^^^^^^^^^^^^^^^^^
  File "/Users/aliosmanyilmaz/opt/anaconda3/envs/shoe/lib/python3.12/site-packages/sentry_sdk/integrations/django/__init__.py", line 641, in execute
    result = real_execute(self, sql, params)
             ^^^^^^^^^^^^^^^^^^^^^^^^^^^^^^^
  File "/Users/aliosmanyilmaz/opt/anaconda3/envs/shoe/lib/python3.12/site-packages/django/db/backends/utils.py", line 67, in execute
    return self._execute_with_wrappers(
           ^^^^^^^^^^^^^^^^^^^^^^^^^^^^
  File "/Users/aliosmanyilmaz/opt/anaconda3/envs/shoe/lib/python3.12/site-packages/django/db/backends/utils.py", line 80, in _execute_with_wrappers
    return executor(sql, params, many, context)
           ^^^^^^^^^^^^^^^^^^^^^^^^^^^^^^^^^^^^
  File "/Users/aliosmanyilmaz/opt/anaconda3/envs/shoe/lib/python3.12/site-packages/django/db/backends/utils.py", line 84, in _execute
    with self.db.wrap_database_errors:
  File "/Users/aliosmanyilmaz/opt/anaconda3/envs/shoe/lib/python3.12/site-packages/django/db/utils.py", line 91, in __exit__
    raise dj_exc_value.with_traceback(traceback) from exc_value
  File "/Users/aliosmanyilmaz/opt/anaconda3/envs/shoe/lib/python3.12/site-packages/django/db/backends/utils.py", line 89, in _execute
    return self.cursor.execute(sql, params)
           ^^^^^^^^^^^^^^^^^^^^^^^^^^^^^^^^
  File "/Users/aliosmanyilmaz/opt/anaconda3/envs/shoe/lib/python3.12/site-packages/django/db/backends/sqlite3/base.py", line 328, in execute
    return super().execute(query, params)
           ^^^^^^^^^^^^^^^^^^^^^^^^^^^^^^
django.db.utils.OperationalError: no such column: api_category.image
ERROR 2023-12-16 12:36:46,507 basehttp "GET /admin/api/category/ HTTP/1.1" 500 254771
ERROR 2023-12-16 12:36:57,865 log Internal Server Error: /admin/api/product/4/change/
Traceback (most recent call last):
  File "/Users/aliosmanyilmaz/opt/anaconda3/envs/shoe/lib/python3.12/site-packages/django/db/backends/utils.py", line 89, in _execute
    return self.cursor.execute(sql, params)
           ^^^^^^^^^^^^^^^^^^^^^^^^^^^^^^^^
  File "/Users/aliosmanyilmaz/opt/anaconda3/envs/shoe/lib/python3.12/site-packages/django/db/backends/sqlite3/base.py", line 328, in execute
    return super().execute(query, params)
           ^^^^^^^^^^^^^^^^^^^^^^^^^^^^^^
sqlite3.OperationalError: no such column: api_category.image

The above exception was the direct cause of the following exception:

Traceback (most recent call last):
  File "/Users/aliosmanyilmaz/opt/anaconda3/envs/shoe/lib/python3.12/site-packages/silk/sql.py", line 89, in execute_sql
    return self._execute_sql(*args, **kwargs)
           ^^^^^^^^^^^^^^^^^^^^^^^^^^^^^^^^^^
  File "/Users/aliosmanyilmaz/opt/anaconda3/envs/shoe/lib/python3.12/site-packages/django/db/models/sql/compiler.py", line 1562, in execute_sql
    cursor.execute(sql, params)
  File "/Users/aliosmanyilmaz/opt/anaconda3/envs/shoe/lib/python3.12/site-packages/django/db/backends/utils.py", line 102, in execute
    return super().execute(sql, params)
           ^^^^^^^^^^^^^^^^^^^^^^^^^^^^
  File "/Users/aliosmanyilmaz/opt/anaconda3/envs/shoe/lib/python3.12/site-packages/sentry_sdk/integrations/django/__init__.py", line 641, in execute
    result = real_execute(self, sql, params)
             ^^^^^^^^^^^^^^^^^^^^^^^^^^^^^^^
  File "/Users/aliosmanyilmaz/opt/anaconda3/envs/shoe/lib/python3.12/site-packages/django/db/backends/utils.py", line 67, in execute
    return self._execute_with_wrappers(
           ^^^^^^^^^^^^^^^^^^^^^^^^^^^^
  File "/Users/aliosmanyilmaz/opt/anaconda3/envs/shoe/lib/python3.12/site-packages/django/db/backends/utils.py", line 80, in _execute_with_wrappers
    return executor(sql, params, many, context)
           ^^^^^^^^^^^^^^^^^^^^^^^^^^^^^^^^^^^^
  File "/Users/aliosmanyilmaz/opt/anaconda3/envs/shoe/lib/python3.12/site-packages/django/db/backends/utils.py", line 84, in _execute
    with self.db.wrap_database_errors:
  File "/Users/aliosmanyilmaz/opt/anaconda3/envs/shoe/lib/python3.12/site-packages/django/db/utils.py", line 91, in __exit__
    raise dj_exc_value.with_traceback(traceback) from exc_value
  File "/Users/aliosmanyilmaz/opt/anaconda3/envs/shoe/lib/python3.12/site-packages/django/db/backends/utils.py", line 89, in _execute
    return self.cursor.execute(sql, params)
           ^^^^^^^^^^^^^^^^^^^^^^^^^^^^^^^^
  File "/Users/aliosmanyilmaz/opt/anaconda3/envs/shoe/lib/python3.12/site-packages/django/db/backends/sqlite3/base.py", line 328, in execute
    return super().execute(query, params)
           ^^^^^^^^^^^^^^^^^^^^^^^^^^^^^^
django.db.utils.OperationalError: no such column: api_category.image

During handling of the above exception, another exception occurred:

Traceback (most recent call last):
  File "/Users/aliosmanyilmaz/opt/anaconda3/envs/shoe/lib/python3.12/site-packages/django/db/backends/utils.py", line 89, in _execute
    return self.cursor.execute(sql, params)
           ^^^^^^^^^^^^^^^^^^^^^^^^^^^^^^^^
  File "/Users/aliosmanyilmaz/opt/anaconda3/envs/shoe/lib/python3.12/site-packages/django/db/backends/sqlite3/base.py", line 328, in execute
    return super().execute(query, params)
           ^^^^^^^^^^^^^^^^^^^^^^^^^^^^^^
sqlite3.OperationalError: no such column: api_category.image

The above exception was the direct cause of the following exception:

Traceback (most recent call last):
  File "/Users/aliosmanyilmaz/opt/anaconda3/envs/shoe/lib/python3.12/site-packages/django/core/handlers/exception.py", line 55, in inner
    response = get_response(request)
               ^^^^^^^^^^^^^^^^^^^^^
  File "/Users/aliosmanyilmaz/opt/anaconda3/envs/shoe/lib/python3.12/site-packages/django/core/handlers/base.py", line 220, in _get_response
    response = response.render()
               ^^^^^^^^^^^^^^^^^
  File "/Users/aliosmanyilmaz/opt/anaconda3/envs/shoe/lib/python3.12/site-packages/sentry_sdk/integrations/django/views.py", line 38, in sentry_patched_render
    return old_render(self)
           ^^^^^^^^^^^^^^^^
  File "/Users/aliosmanyilmaz/opt/anaconda3/envs/shoe/lib/python3.12/site-packages/django/template/response.py", line 114, in render
    self.content = self.rendered_content
                   ^^^^^^^^^^^^^^^^^^^^^
  File "/Users/aliosmanyilmaz/opt/anaconda3/envs/shoe/lib/python3.12/site-packages/sentry_sdk/integrations/django/templates.py", line 75, in rendered_content
    return real_rendered_content.fget(self)
           ^^^^^^^^^^^^^^^^^^^^^^^^^^^^^^^^
  File "/Users/aliosmanyilmaz/opt/anaconda3/envs/shoe/lib/python3.12/site-packages/django/template/response.py", line 92, in rendered_content
    return template.render(context, self._request)
           ^^^^^^^^^^^^^^^^^^^^^^^^^^^^^^^^^^^^^^^
  File "/Users/aliosmanyilmaz/opt/anaconda3/envs/shoe/lib/python3.12/site-packages/django/template/backends/django.py", line 61, in render
    return self.template.render(context)
           ^^^^^^^^^^^^^^^^^^^^^^^^^^^^^
  File "/Users/aliosmanyilmaz/opt/anaconda3/envs/shoe/lib/python3.12/site-packages/django/template/base.py", line 175, in render
    return self._render(context)
           ^^^^^^^^^^^^^^^^^^^^^
  File "/Users/aliosmanyilmaz/opt/anaconda3/envs/shoe/lib/python3.12/site-packages/django/template/base.py", line 167, in _render
    return self.nodelist.render(context)
           ^^^^^^^^^^^^^^^^^^^^^^^^^^^^^
  File "/Users/aliosmanyilmaz/opt/anaconda3/envs/shoe/lib/python3.12/site-packages/django/template/base.py", line 1005, in render
    return SafeString("".join([node.render_annotated(context) for node in self]))
                               ^^^^^^^^^^^^^^^^^^^^^^^^^^^^^^
  File "/Users/aliosmanyilmaz/opt/anaconda3/envs/shoe/lib/python3.12/site-packages/django/template/base.py", line 966, in render_annotated
    return self.render(context)
           ^^^^^^^^^^^^^^^^^^^^
  File "/Users/aliosmanyilmaz/opt/anaconda3/envs/shoe/lib/python3.12/site-packages/django/template/loader_tags.py", line 157, in render
    return compiled_parent._render(context)
           ^^^^^^^^^^^^^^^^^^^^^^^^^^^^^^^^
  File "/Users/aliosmanyilmaz/opt/anaconda3/envs/shoe/lib/python3.12/site-packages/django/template/base.py", line 167, in _render
    return self.nodelist.render(context)
           ^^^^^^^^^^^^^^^^^^^^^^^^^^^^^
  File "/Users/aliosmanyilmaz/opt/anaconda3/envs/shoe/lib/python3.12/site-packages/django/template/base.py", line 1005, in render
    return SafeString("".join([node.render_annotated(context) for node in self]))
                               ^^^^^^^^^^^^^^^^^^^^^^^^^^^^^^
  File "/Users/aliosmanyilmaz/opt/anaconda3/envs/shoe/lib/python3.12/site-packages/django/template/base.py", line 966, in render_annotated
    return self.render(context)
           ^^^^^^^^^^^^^^^^^^^^
  File "/Users/aliosmanyilmaz/opt/anaconda3/envs/shoe/lib/python3.12/site-packages/django/template/loader_tags.py", line 157, in render
    return compiled_parent._render(context)
           ^^^^^^^^^^^^^^^^^^^^^^^^^^^^^^^^
  File "/Users/aliosmanyilmaz/opt/anaconda3/envs/shoe/lib/python3.12/site-packages/django/template/base.py", line 167, in _render
    return self.nodelist.render(context)
           ^^^^^^^^^^^^^^^^^^^^^^^^^^^^^
  File "/Users/aliosmanyilmaz/opt/anaconda3/envs/shoe/lib/python3.12/site-packages/django/template/base.py", line 1005, in render
    return SafeString("".join([node.render_annotated(context) for node in self]))
                               ^^^^^^^^^^^^^^^^^^^^^^^^^^^^^^
  File "/Users/aliosmanyilmaz/opt/anaconda3/envs/shoe/lib/python3.12/site-packages/django/template/base.py", line 966, in render_annotated
    return self.render(context)
           ^^^^^^^^^^^^^^^^^^^^
  File "/Users/aliosmanyilmaz/opt/anaconda3/envs/shoe/lib/python3.12/site-packages/django/template/loader_tags.py", line 63, in render
    result = block.nodelist.render(context)
             ^^^^^^^^^^^^^^^^^^^^^^^^^^^^^^
  File "/Users/aliosmanyilmaz/opt/anaconda3/envs/shoe/lib/python3.12/site-packages/django/template/base.py", line 1005, in render
    return SafeString("".join([node.render_annotated(context) for node in self]))
                               ^^^^^^^^^^^^^^^^^^^^^^^^^^^^^^
  File "/Users/aliosmanyilmaz/opt/anaconda3/envs/shoe/lib/python3.12/site-packages/django/template/base.py", line 966, in render_annotated
    return self.render(context)
           ^^^^^^^^^^^^^^^^^^^^
  File "/Users/aliosmanyilmaz/opt/anaconda3/envs/shoe/lib/python3.12/site-packages/django/template/loader_tags.py", line 63, in render
    result = block.nodelist.render(context)
             ^^^^^^^^^^^^^^^^^^^^^^^^^^^^^^
  File "/Users/aliosmanyilmaz/opt/anaconda3/envs/shoe/lib/python3.12/site-packages/django/template/base.py", line 1005, in render
    return SafeString("".join([node.render_annotated(context) for node in self]))
                               ^^^^^^^^^^^^^^^^^^^^^^^^^^^^^^
  File "/Users/aliosmanyilmaz/opt/anaconda3/envs/shoe/lib/python3.12/site-packages/django/template/base.py", line 966, in render_annotated
    return self.render(context)
           ^^^^^^^^^^^^^^^^^^^^
  File "/Users/aliosmanyilmaz/opt/anaconda3/envs/shoe/lib/python3.12/site-packages/django/template/defaulttags.py", line 238, in render
    nodelist.append(node.render_annotated(context))
                    ^^^^^^^^^^^^^^^^^^^^^^^^^^^^^^
  File "/Users/aliosmanyilmaz/opt/anaconda3/envs/shoe/lib/python3.12/site-packages/django/template/base.py", line 966, in render_annotated
    return self.render(context)
           ^^^^^^^^^^^^^^^^^^^^
  File "/Users/aliosmanyilmaz/opt/anaconda3/envs/shoe/lib/python3.12/site-packages/django/template/loader_tags.py", line 208, in render
    return template.render(context)
           ^^^^^^^^^^^^^^^^^^^^^^^^
  File "/Users/aliosmanyilmaz/opt/anaconda3/envs/shoe/lib/python3.12/site-packages/django/template/base.py", line 177, in render
    return self._render(context)
           ^^^^^^^^^^^^^^^^^^^^^
  File "/Users/aliosmanyilmaz/opt/anaconda3/envs/shoe/lib/python3.12/site-packages/django/template/base.py", line 167, in _render
    return self.nodelist.render(context)
           ^^^^^^^^^^^^^^^^^^^^^^^^^^^^^
  File "/Users/aliosmanyilmaz/opt/anaconda3/envs/shoe/lib/python3.12/site-packages/django/template/base.py", line 1005, in render
    return SafeString("".join([node.render_annotated(context) for node in self]))
                               ^^^^^^^^^^^^^^^^^^^^^^^^^^^^^^
  File "/Users/aliosmanyilmaz/opt/anaconda3/envs/shoe/lib/python3.12/site-packages/django/template/base.py", line 966, in render_annotated
    return self.render(context)
           ^^^^^^^^^^^^^^^^^^^^
  File "/Users/aliosmanyilmaz/opt/anaconda3/envs/shoe/lib/python3.12/site-packages/django/template/defaulttags.py", line 238, in render
    nodelist.append(node.render_annotated(context))
                    ^^^^^^^^^^^^^^^^^^^^^^^^^^^^^^
  File "/Users/aliosmanyilmaz/opt/anaconda3/envs/shoe/lib/python3.12/site-packages/django/template/base.py", line 966, in render_annotated
    return self.render(context)
           ^^^^^^^^^^^^^^^^^^^^
  File "/Users/aliosmanyilmaz/opt/anaconda3/envs/shoe/lib/python3.12/site-packages/django/template/defaulttags.py", line 238, in render
    nodelist.append(node.render_annotated(context))
                    ^^^^^^^^^^^^^^^^^^^^^^^^^^^^^^
  File "/Users/aliosmanyilmaz/opt/anaconda3/envs/shoe/lib/python3.12/site-packages/django/template/base.py", line 966, in render_annotated
    return self.render(context)
           ^^^^^^^^^^^^^^^^^^^^
  File "/Users/aliosmanyilmaz/opt/anaconda3/envs/shoe/lib/python3.12/site-packages/django/template/defaulttags.py", line 321, in render
    return nodelist.render(context)
           ^^^^^^^^^^^^^^^^^^^^^^^^
  File "/Users/aliosmanyilmaz/opt/anaconda3/envs/shoe/lib/python3.12/site-packages/django/template/base.py", line 1005, in render
    return SafeString("".join([node.render_annotated(context) for node in self]))
                               ^^^^^^^^^^^^^^^^^^^^^^^^^^^^^^
  File "/Users/aliosmanyilmaz/opt/anaconda3/envs/shoe/lib/python3.12/site-packages/django/template/base.py", line 966, in render_annotated
    return self.render(context)
           ^^^^^^^^^^^^^^^^^^^^
  File "/Users/aliosmanyilmaz/opt/anaconda3/envs/shoe/lib/python3.12/site-packages/django/template/defaulttags.py", line 321, in render
    return nodelist.render(context)
           ^^^^^^^^^^^^^^^^^^^^^^^^
  File "/Users/aliosmanyilmaz/opt/anaconda3/envs/shoe/lib/python3.12/site-packages/django/template/base.py", line 1005, in render
    return SafeString("".join([node.render_annotated(context) for node in self]))
                               ^^^^^^^^^^^^^^^^^^^^^^^^^^^^^^
  File "/Users/aliosmanyilmaz/opt/anaconda3/envs/shoe/lib/python3.12/site-packages/django/template/base.py", line 966, in render_annotated
    return self.render(context)
           ^^^^^^^^^^^^^^^^^^^^
  File "/Users/aliosmanyilmaz/opt/anaconda3/envs/shoe/lib/python3.12/site-packages/django/template/base.py", line 1070, in render
    return render_value_in_context(output, context)
           ^^^^^^^^^^^^^^^^^^^^^^^^^^^^^^^^^^^^^^^^
  File "/Users/aliosmanyilmaz/opt/anaconda3/envs/shoe/lib/python3.12/site-packages/django/template/base.py", line 1047, in render_value_in_context
    value = str(value)
            ^^^^^^^^^^
  File "/Users/aliosmanyilmaz/opt/anaconda3/envs/shoe/lib/python3.12/site-packages/django/utils/html.py", line 420, in <lambda>
    klass.__str__ = lambda self: mark_safe(klass_str(self))
                                           ^^^^^^^^^^^^^^^
  File "/Users/aliosmanyilmaz/opt/anaconda3/envs/shoe/lib/python3.12/site-packages/django/forms/boundfield.py", line 34, in __str__
    return self.as_widget()
           ^^^^^^^^^^^^^^^^
  File "/Users/aliosmanyilmaz/opt/anaconda3/envs/shoe/lib/python3.12/site-packages/django/forms/boundfield.py", line 107, in as_widget
    return widget.render(
           ^^^^^^^^^^^^^^
  File "/Users/aliosmanyilmaz/opt/anaconda3/envs/shoe/lib/python3.12/site-packages/django/forms/widgets.py", line 280, in render
    context = self.get_context(name, value, attrs)
              ^^^^^^^^^^^^^^^^^^^^^^^^^^^^^^^^^^^^
  File "/Users/aliosmanyilmaz/opt/anaconda3/envs/shoe/lib/python3.12/site-packages/django/contrib/admin/widgets.py", line 320, in get_context
    "rendered_widget": self.widget.render(name, value, attrs),
                       ^^^^^^^^^^^^^^^^^^^^^^^^^^^^^^^^^^^^^^
  File "/Users/aliosmanyilmaz/opt/anaconda3/envs/shoe/lib/python3.12/site-packages/django/forms/widgets.py", line 280, in render
    context = self.get_context(name, value, attrs)
              ^^^^^^^^^^^^^^^^^^^^^^^^^^^^^^^^^^^^
  File "/Users/aliosmanyilmaz/opt/anaconda3/envs/shoe/lib/python3.12/site-packages/django/forms/widgets.py", line 758, in get_context
    context = super().get_context(name, value, attrs)
              ^^^^^^^^^^^^^^^^^^^^^^^^^^^^^^^^^^^^^^^
  File "/Users/aliosmanyilmaz/opt/anaconda3/envs/shoe/lib/python3.12/site-packages/django/forms/widgets.py", line 717, in get_context
    context["widget"]["optgroups"] = self.optgroups(
                                     ^^^^^^^^^^^^^^^
  File "/Users/aliosmanyilmaz/opt/anaconda3/envs/shoe/lib/python3.12/site-packages/django/forms/widgets.py", line 657, in optgroups
    for index, (option_value, option_label) in enumerate(self.choices):
  File "/Users/aliosmanyilmaz/opt/anaconda3/envs/shoe/lib/python3.12/site-packages/django/forms/models.py", line 1403, in __iter__
    for obj in queryset:
  File "/Users/aliosmanyilmaz/opt/anaconda3/envs/shoe/lib/python3.12/site-packages/django/db/models/query.py", line 516, in _iterator
    yield from iterable
  File "/Users/aliosmanyilmaz/opt/anaconda3/envs/shoe/lib/python3.12/site-packages/django/db/models/query.py", line 91, in __iter__
    results = compiler.execute_sql(
              ^^^^^^^^^^^^^^^^^^^^^
  File "/Users/aliosmanyilmaz/opt/anaconda3/envs/shoe/lib/python3.12/site-packages/silk/sql.py", line 96, in execute_sql
    query_dict['analysis'] = _explain_query(self.connection, q, params)
                             ^^^^^^^^^^^^^^^^^^^^^^^^^^^^^^^^^^^^^^^^^^
  File "/Users/aliosmanyilmaz/opt/anaconda3/envs/shoe/lib/python3.12/site-packages/silk/sql.py", line 58, in _explain_query
    cur.execute(prefixed_query, params)
  File "/Users/aliosmanyilmaz/opt/anaconda3/envs/shoe/lib/python3.12/site-packages/django/db/backends/utils.py", line 102, in execute
    return super().execute(sql, params)
           ^^^^^^^^^^^^^^^^^^^^^^^^^^^^
  File "/Users/aliosmanyilmaz/opt/anaconda3/envs/shoe/lib/python3.12/site-packages/sentry_sdk/integrations/django/__init__.py", line 641, in execute
    result = real_execute(self, sql, params)
             ^^^^^^^^^^^^^^^^^^^^^^^^^^^^^^^
  File "/Users/aliosmanyilmaz/opt/anaconda3/envs/shoe/lib/python3.12/site-packages/django/db/backends/utils.py", line 67, in execute
    return self._execute_with_wrappers(
           ^^^^^^^^^^^^^^^^^^^^^^^^^^^^
  File "/Users/aliosmanyilmaz/opt/anaconda3/envs/shoe/lib/python3.12/site-packages/django/db/backends/utils.py", line 80, in _execute_with_wrappers
    return executor(sql, params, many, context)
           ^^^^^^^^^^^^^^^^^^^^^^^^^^^^^^^^^^^^
  File "/Users/aliosmanyilmaz/opt/anaconda3/envs/shoe/lib/python3.12/site-packages/django/db/backends/utils.py", line 84, in _execute
    with self.db.wrap_database_errors:
  File "/Users/aliosmanyilmaz/opt/anaconda3/envs/shoe/lib/python3.12/site-packages/django/db/utils.py", line 91, in __exit__
    raise dj_exc_value.with_traceback(traceback) from exc_value
  File "/Users/aliosmanyilmaz/opt/anaconda3/envs/shoe/lib/python3.12/site-packages/django/db/backends/utils.py", line 89, in _execute
    return self.cursor.execute(sql, params)
           ^^^^^^^^^^^^^^^^^^^^^^^^^^^^^^^^
  File "/Users/aliosmanyilmaz/opt/anaconda3/envs/shoe/lib/python3.12/site-packages/django/db/backends/sqlite3/base.py", line 328, in execute
    return super().execute(query, params)
           ^^^^^^^^^^^^^^^^^^^^^^^^^^^^^^
django.db.utils.OperationalError: no such column: api_category.image
ERROR 2023-12-16 12:36:57,888 basehttp "GET /admin/api/product/4/change/ HTTP/1.1" 500 745474
ERROR 2023-12-16 12:37:03,667 log Internal Server Error: /admin/api/category/
Traceback (most recent call last):
  File "/Users/aliosmanyilmaz/opt/anaconda3/envs/shoe/lib/python3.12/site-packages/django/db/backends/utils.py", line 89, in _execute
    return self.cursor.execute(sql, params)
           ^^^^^^^^^^^^^^^^^^^^^^^^^^^^^^^^
  File "/Users/aliosmanyilmaz/opt/anaconda3/envs/shoe/lib/python3.12/site-packages/django/db/backends/sqlite3/base.py", line 328, in execute
    return super().execute(query, params)
           ^^^^^^^^^^^^^^^^^^^^^^^^^^^^^^
sqlite3.OperationalError: no such column: api_category.image

The above exception was the direct cause of the following exception:

Traceback (most recent call last):
  File "/Users/aliosmanyilmaz/opt/anaconda3/envs/shoe/lib/python3.12/site-packages/silk/sql.py", line 89, in execute_sql
    return self._execute_sql(*args, **kwargs)
           ^^^^^^^^^^^^^^^^^^^^^^^^^^^^^^^^^^
  File "/Users/aliosmanyilmaz/opt/anaconda3/envs/shoe/lib/python3.12/site-packages/django/db/models/sql/compiler.py", line 1562, in execute_sql
    cursor.execute(sql, params)
  File "/Users/aliosmanyilmaz/opt/anaconda3/envs/shoe/lib/python3.12/site-packages/django/db/backends/utils.py", line 102, in execute
    return super().execute(sql, params)
           ^^^^^^^^^^^^^^^^^^^^^^^^^^^^
  File "/Users/aliosmanyilmaz/opt/anaconda3/envs/shoe/lib/python3.12/site-packages/sentry_sdk/integrations/django/__init__.py", line 641, in execute
    result = real_execute(self, sql, params)
             ^^^^^^^^^^^^^^^^^^^^^^^^^^^^^^^
  File "/Users/aliosmanyilmaz/opt/anaconda3/envs/shoe/lib/python3.12/site-packages/django/db/backends/utils.py", line 67, in execute
    return self._execute_with_wrappers(
           ^^^^^^^^^^^^^^^^^^^^^^^^^^^^
  File "/Users/aliosmanyilmaz/opt/anaconda3/envs/shoe/lib/python3.12/site-packages/django/db/backends/utils.py", line 80, in _execute_with_wrappers
    return executor(sql, params, many, context)
           ^^^^^^^^^^^^^^^^^^^^^^^^^^^^^^^^^^^^
  File "/Users/aliosmanyilmaz/opt/anaconda3/envs/shoe/lib/python3.12/site-packages/django/db/backends/utils.py", line 84, in _execute
    with self.db.wrap_database_errors:
  File "/Users/aliosmanyilmaz/opt/anaconda3/envs/shoe/lib/python3.12/site-packages/django/db/utils.py", line 91, in __exit__
    raise dj_exc_value.with_traceback(traceback) from exc_value
  File "/Users/aliosmanyilmaz/opt/anaconda3/envs/shoe/lib/python3.12/site-packages/django/db/backends/utils.py", line 89, in _execute
    return self.cursor.execute(sql, params)
           ^^^^^^^^^^^^^^^^^^^^^^^^^^^^^^^^
  File "/Users/aliosmanyilmaz/opt/anaconda3/envs/shoe/lib/python3.12/site-packages/django/db/backends/sqlite3/base.py", line 328, in execute
    return super().execute(query, params)
           ^^^^^^^^^^^^^^^^^^^^^^^^^^^^^^
django.db.utils.OperationalError: no such column: api_category.image

During handling of the above exception, another exception occurred:

Traceback (most recent call last):
  File "/Users/aliosmanyilmaz/opt/anaconda3/envs/shoe/lib/python3.12/site-packages/django/db/backends/utils.py", line 89, in _execute
    return self.cursor.execute(sql, params)
           ^^^^^^^^^^^^^^^^^^^^^^^^^^^^^^^^
  File "/Users/aliosmanyilmaz/opt/anaconda3/envs/shoe/lib/python3.12/site-packages/django/db/backends/sqlite3/base.py", line 328, in execute
    return super().execute(query, params)
           ^^^^^^^^^^^^^^^^^^^^^^^^^^^^^^
sqlite3.OperationalError: no such column: api_category.image

The above exception was the direct cause of the following exception:

Traceback (most recent call last):
  File "/Users/aliosmanyilmaz/opt/anaconda3/envs/shoe/lib/python3.12/site-packages/django/core/handlers/exception.py", line 55, in inner
    response = get_response(request)
               ^^^^^^^^^^^^^^^^^^^^^
  File "/Users/aliosmanyilmaz/opt/anaconda3/envs/shoe/lib/python3.12/site-packages/django/core/handlers/base.py", line 197, in _get_response
    response = wrapped_callback(request, *callback_args, **callback_kwargs)
               ^^^^^^^^^^^^^^^^^^^^^^^^^^^^^^^^^^^^^^^^^^^^^^^^^^^^^^^^^^^^
  File "/Users/aliosmanyilmaz/opt/anaconda3/envs/shoe/lib/python3.12/site-packages/sentry_sdk/integrations/django/views.py", line 84, in sentry_wrapped_callback
    return callback(request, *args, **kwargs)
           ^^^^^^^^^^^^^^^^^^^^^^^^^^^^^^^^^^
  File "/Users/aliosmanyilmaz/opt/anaconda3/envs/shoe/lib/python3.12/site-packages/django/contrib/admin/options.py", line 688, in wrapper
    return self.admin_site.admin_view(view)(*args, **kwargs)
           ^^^^^^^^^^^^^^^^^^^^^^^^^^^^^^^^^^^^^^^^^^^^^^^^^
  File "/Users/aliosmanyilmaz/opt/anaconda3/envs/shoe/lib/python3.12/site-packages/django/utils/decorators.py", line 134, in _wrapper_view
    response = view_func(request, *args, **kwargs)
               ^^^^^^^^^^^^^^^^^^^^^^^^^^^^^^^^^^^
  File "/Users/aliosmanyilmaz/opt/anaconda3/envs/shoe/lib/python3.12/site-packages/django/views/decorators/cache.py", line 62, in _wrapper_view_func
    response = view_func(request, *args, **kwargs)
               ^^^^^^^^^^^^^^^^^^^^^^^^^^^^^^^^^^^
  File "/Users/aliosmanyilmaz/opt/anaconda3/envs/shoe/lib/python3.12/site-packages/django/contrib/admin/sites.py", line 242, in inner
    return view(request, *args, **kwargs)
           ^^^^^^^^^^^^^^^^^^^^^^^^^^^^^^
  File "/Users/aliosmanyilmaz/opt/anaconda3/envs/shoe/lib/python3.12/site-packages/django/utils/decorators.py", line 46, in _wrapper
    return bound_method(*args, **kwargs)
           ^^^^^^^^^^^^^^^^^^^^^^^^^^^^^
  File "/Users/aliosmanyilmaz/opt/anaconda3/envs/shoe/lib/python3.12/site-packages/django/utils/decorators.py", line 134, in _wrapper_view
    response = view_func(request, *args, **kwargs)
               ^^^^^^^^^^^^^^^^^^^^^^^^^^^^^^^^^^^
  File "/Users/aliosmanyilmaz/opt/anaconda3/envs/shoe/lib/python3.12/site-packages/django/contrib/admin/options.py", line 2065, in changelist_view
    "selection_note": _("0 of %(cnt)s selected") % {"cnt": len(cl.result_list)},
                                                           ^^^^^^^^^^^^^^^^^^^
  File "/Users/aliosmanyilmaz/opt/anaconda3/envs/shoe/lib/python3.12/site-packages/django/db/models/query.py", line 380, in __len__
    self._fetch_all()
  File "/Users/aliosmanyilmaz/opt/anaconda3/envs/shoe/lib/python3.12/site-packages/django/db/models/query.py", line 1881, in _fetch_all
    self._result_cache = list(self._iterable_class(self))
                         ^^^^^^^^^^^^^^^^^^^^^^^^^^^^^^^^
  File "/Users/aliosmanyilmaz/opt/anaconda3/envs/shoe/lib/python3.12/site-packages/django/db/models/query.py", line 91, in __iter__
    results = compiler.execute_sql(
              ^^^^^^^^^^^^^^^^^^^^^
  File "/Users/aliosmanyilmaz/opt/anaconda3/envs/shoe/lib/python3.12/site-packages/silk/sql.py", line 96, in execute_sql
    query_dict['analysis'] = _explain_query(self.connection, q, params)
                             ^^^^^^^^^^^^^^^^^^^^^^^^^^^^^^^^^^^^^^^^^^
  File "/Users/aliosmanyilmaz/opt/anaconda3/envs/shoe/lib/python3.12/site-packages/silk/sql.py", line 58, in _explain_query
    cur.execute(prefixed_query, params)
  File "/Users/aliosmanyilmaz/opt/anaconda3/envs/shoe/lib/python3.12/site-packages/django/db/backends/utils.py", line 102, in execute
    return super().execute(sql, params)
           ^^^^^^^^^^^^^^^^^^^^^^^^^^^^
  File "/Users/aliosmanyilmaz/opt/anaconda3/envs/shoe/lib/python3.12/site-packages/sentry_sdk/integrations/django/__init__.py", line 641, in execute
    result = real_execute(self, sql, params)
             ^^^^^^^^^^^^^^^^^^^^^^^^^^^^^^^
  File "/Users/aliosmanyilmaz/opt/anaconda3/envs/shoe/lib/python3.12/site-packages/django/db/backends/utils.py", line 67, in execute
    return self._execute_with_wrappers(
           ^^^^^^^^^^^^^^^^^^^^^^^^^^^^
  File "/Users/aliosmanyilmaz/opt/anaconda3/envs/shoe/lib/python3.12/site-packages/django/db/backends/utils.py", line 80, in _execute_with_wrappers
    return executor(sql, params, many, context)
           ^^^^^^^^^^^^^^^^^^^^^^^^^^^^^^^^^^^^
  File "/Users/aliosmanyilmaz/opt/anaconda3/envs/shoe/lib/python3.12/site-packages/django/db/backends/utils.py", line 84, in _execute
    with self.db.wrap_database_errors:
  File "/Users/aliosmanyilmaz/opt/anaconda3/envs/shoe/lib/python3.12/site-packages/django/db/utils.py", line 91, in __exit__
    raise dj_exc_value.with_traceback(traceback) from exc_value
  File "/Users/aliosmanyilmaz/opt/anaconda3/envs/shoe/lib/python3.12/site-packages/django/db/backends/utils.py", line 89, in _execute
    return self.cursor.execute(sql, params)
           ^^^^^^^^^^^^^^^^^^^^^^^^^^^^^^^^
  File "/Users/aliosmanyilmaz/opt/anaconda3/envs/shoe/lib/python3.12/site-packages/django/db/backends/sqlite3/base.py", line 328, in execute
    return super().execute(query, params)
           ^^^^^^^^^^^^^^^^^^^^^^^^^^^^^^
django.db.utils.OperationalError: no such column: api_category.image
ERROR 2023-12-16 12:37:03,684 basehttp "GET /admin/api/category/ HTTP/1.1" 500 254642
ERROR 2023-12-16 12:38:27,317 log Internal Server Error: /admin/api/product/4/change/
Traceback (most recent call last):
  File "/Users/aliosmanyilmaz/opt/anaconda3/envs/shoe/lib/python3.12/site-packages/django/db/backends/utils.py", line 89, in _execute
    return self.cursor.execute(sql, params)
           ^^^^^^^^^^^^^^^^^^^^^^^^^^^^^^^^
  File "/Users/aliosmanyilmaz/opt/anaconda3/envs/shoe/lib/python3.12/site-packages/django/db/backends/sqlite3/base.py", line 328, in execute
    return super().execute(query, params)
           ^^^^^^^^^^^^^^^^^^^^^^^^^^^^^^
sqlite3.OperationalError: no such column: api_category.image

The above exception was the direct cause of the following exception:

Traceback (most recent call last):
  File "/Users/aliosmanyilmaz/opt/anaconda3/envs/shoe/lib/python3.12/site-packages/silk/sql.py", line 89, in execute_sql
    return self._execute_sql(*args, **kwargs)
           ^^^^^^^^^^^^^^^^^^^^^^^^^^^^^^^^^^
  File "/Users/aliosmanyilmaz/opt/anaconda3/envs/shoe/lib/python3.12/site-packages/django/db/models/sql/compiler.py", line 1562, in execute_sql
    cursor.execute(sql, params)
  File "/Users/aliosmanyilmaz/opt/anaconda3/envs/shoe/lib/python3.12/site-packages/django/db/backends/utils.py", line 102, in execute
    return super().execute(sql, params)
           ^^^^^^^^^^^^^^^^^^^^^^^^^^^^
  File "/Users/aliosmanyilmaz/opt/anaconda3/envs/shoe/lib/python3.12/site-packages/sentry_sdk/integrations/django/__init__.py", line 641, in execute
    result = real_execute(self, sql, params)
             ^^^^^^^^^^^^^^^^^^^^^^^^^^^^^^^
  File "/Users/aliosmanyilmaz/opt/anaconda3/envs/shoe/lib/python3.12/site-packages/django/db/backends/utils.py", line 67, in execute
    return self._execute_with_wrappers(
           ^^^^^^^^^^^^^^^^^^^^^^^^^^^^
  File "/Users/aliosmanyilmaz/opt/anaconda3/envs/shoe/lib/python3.12/site-packages/django/db/backends/utils.py", line 80, in _execute_with_wrappers
    return executor(sql, params, many, context)
           ^^^^^^^^^^^^^^^^^^^^^^^^^^^^^^^^^^^^
  File "/Users/aliosmanyilmaz/opt/anaconda3/envs/shoe/lib/python3.12/site-packages/django/db/backends/utils.py", line 84, in _execute
    with self.db.wrap_database_errors:
  File "/Users/aliosmanyilmaz/opt/anaconda3/envs/shoe/lib/python3.12/site-packages/django/db/utils.py", line 91, in __exit__
    raise dj_exc_value.with_traceback(traceback) from exc_value
  File "/Users/aliosmanyilmaz/opt/anaconda3/envs/shoe/lib/python3.12/site-packages/django/db/backends/utils.py", line 89, in _execute
    return self.cursor.execute(sql, params)
           ^^^^^^^^^^^^^^^^^^^^^^^^^^^^^^^^
  File "/Users/aliosmanyilmaz/opt/anaconda3/envs/shoe/lib/python3.12/site-packages/django/db/backends/sqlite3/base.py", line 328, in execute
    return super().execute(query, params)
           ^^^^^^^^^^^^^^^^^^^^^^^^^^^^^^
django.db.utils.OperationalError: no such column: api_category.image

During handling of the above exception, another exception occurred:

Traceback (most recent call last):
  File "/Users/aliosmanyilmaz/opt/anaconda3/envs/shoe/lib/python3.12/site-packages/django/db/backends/utils.py", line 89, in _execute
    return self.cursor.execute(sql, params)
           ^^^^^^^^^^^^^^^^^^^^^^^^^^^^^^^^
  File "/Users/aliosmanyilmaz/opt/anaconda3/envs/shoe/lib/python3.12/site-packages/django/db/backends/sqlite3/base.py", line 328, in execute
    return super().execute(query, params)
           ^^^^^^^^^^^^^^^^^^^^^^^^^^^^^^
sqlite3.OperationalError: no such column: api_category.image

The above exception was the direct cause of the following exception:

Traceback (most recent call last):
  File "/Users/aliosmanyilmaz/opt/anaconda3/envs/shoe/lib/python3.12/site-packages/django/core/handlers/exception.py", line 55, in inner
    response = get_response(request)
               ^^^^^^^^^^^^^^^^^^^^^
  File "/Users/aliosmanyilmaz/opt/anaconda3/envs/shoe/lib/python3.12/site-packages/django/core/handlers/base.py", line 220, in _get_response
    response = response.render()
               ^^^^^^^^^^^^^^^^^
  File "/Users/aliosmanyilmaz/opt/anaconda3/envs/shoe/lib/python3.12/site-packages/sentry_sdk/integrations/django/views.py", line 38, in sentry_patched_render
    return old_render(self)
           ^^^^^^^^^^^^^^^^
  File "/Users/aliosmanyilmaz/opt/anaconda3/envs/shoe/lib/python3.12/site-packages/django/template/response.py", line 114, in render
    self.content = self.rendered_content
                   ^^^^^^^^^^^^^^^^^^^^^
  File "/Users/aliosmanyilmaz/opt/anaconda3/envs/shoe/lib/python3.12/site-packages/sentry_sdk/integrations/django/templates.py", line 75, in rendered_content
    return real_rendered_content.fget(self)
           ^^^^^^^^^^^^^^^^^^^^^^^^^^^^^^^^
  File "/Users/aliosmanyilmaz/opt/anaconda3/envs/shoe/lib/python3.12/site-packages/django/template/response.py", line 92, in rendered_content
    return template.render(context, self._request)
           ^^^^^^^^^^^^^^^^^^^^^^^^^^^^^^^^^^^^^^^
  File "/Users/aliosmanyilmaz/opt/anaconda3/envs/shoe/lib/python3.12/site-packages/django/template/backends/django.py", line 61, in render
    return self.template.render(context)
           ^^^^^^^^^^^^^^^^^^^^^^^^^^^^^
  File "/Users/aliosmanyilmaz/opt/anaconda3/envs/shoe/lib/python3.12/site-packages/django/template/base.py", line 175, in render
    return self._render(context)
           ^^^^^^^^^^^^^^^^^^^^^
  File "/Users/aliosmanyilmaz/opt/anaconda3/envs/shoe/lib/python3.12/site-packages/django/template/base.py", line 167, in _render
    return self.nodelist.render(context)
           ^^^^^^^^^^^^^^^^^^^^^^^^^^^^^
  File "/Users/aliosmanyilmaz/opt/anaconda3/envs/shoe/lib/python3.12/site-packages/django/template/base.py", line 1005, in render
    return SafeString("".join([node.render_annotated(context) for node in self]))
                               ^^^^^^^^^^^^^^^^^^^^^^^^^^^^^^
  File "/Users/aliosmanyilmaz/opt/anaconda3/envs/shoe/lib/python3.12/site-packages/django/template/base.py", line 966, in render_annotated
    return self.render(context)
           ^^^^^^^^^^^^^^^^^^^^
  File "/Users/aliosmanyilmaz/opt/anaconda3/envs/shoe/lib/python3.12/site-packages/django/template/loader_tags.py", line 157, in render
    return compiled_parent._render(context)
           ^^^^^^^^^^^^^^^^^^^^^^^^^^^^^^^^
  File "/Users/aliosmanyilmaz/opt/anaconda3/envs/shoe/lib/python3.12/site-packages/django/template/base.py", line 167, in _render
    return self.nodelist.render(context)
           ^^^^^^^^^^^^^^^^^^^^^^^^^^^^^
  File "/Users/aliosmanyilmaz/opt/anaconda3/envs/shoe/lib/python3.12/site-packages/django/template/base.py", line 1005, in render
    return SafeString("".join([node.render_annotated(context) for node in self]))
                               ^^^^^^^^^^^^^^^^^^^^^^^^^^^^^^
  File "/Users/aliosmanyilmaz/opt/anaconda3/envs/shoe/lib/python3.12/site-packages/django/template/base.py", line 966, in render_annotated
    return self.render(context)
           ^^^^^^^^^^^^^^^^^^^^
  File "/Users/aliosmanyilmaz/opt/anaconda3/envs/shoe/lib/python3.12/site-packages/django/template/loader_tags.py", line 157, in render
    return compiled_parent._render(context)
           ^^^^^^^^^^^^^^^^^^^^^^^^^^^^^^^^
  File "/Users/aliosmanyilmaz/opt/anaconda3/envs/shoe/lib/python3.12/site-packages/django/template/base.py", line 167, in _render
    return self.nodelist.render(context)
           ^^^^^^^^^^^^^^^^^^^^^^^^^^^^^
  File "/Users/aliosmanyilmaz/opt/anaconda3/envs/shoe/lib/python3.12/site-packages/django/template/base.py", line 1005, in render
    return SafeString("".join([node.render_annotated(context) for node in self]))
                               ^^^^^^^^^^^^^^^^^^^^^^^^^^^^^^
  File "/Users/aliosmanyilmaz/opt/anaconda3/envs/shoe/lib/python3.12/site-packages/django/template/base.py", line 966, in render_annotated
    return self.render(context)
           ^^^^^^^^^^^^^^^^^^^^
  File "/Users/aliosmanyilmaz/opt/anaconda3/envs/shoe/lib/python3.12/site-packages/django/template/loader_tags.py", line 63, in render
    result = block.nodelist.render(context)
             ^^^^^^^^^^^^^^^^^^^^^^^^^^^^^^
  File "/Users/aliosmanyilmaz/opt/anaconda3/envs/shoe/lib/python3.12/site-packages/django/template/base.py", line 1005, in render
    return SafeString("".join([node.render_annotated(context) for node in self]))
                               ^^^^^^^^^^^^^^^^^^^^^^^^^^^^^^
  File "/Users/aliosmanyilmaz/opt/anaconda3/envs/shoe/lib/python3.12/site-packages/django/template/base.py", line 966, in render_annotated
    return self.render(context)
           ^^^^^^^^^^^^^^^^^^^^
  File "/Users/aliosmanyilmaz/opt/anaconda3/envs/shoe/lib/python3.12/site-packages/django/template/loader_tags.py", line 63, in render
    result = block.nodelist.render(context)
             ^^^^^^^^^^^^^^^^^^^^^^^^^^^^^^
  File "/Users/aliosmanyilmaz/opt/anaconda3/envs/shoe/lib/python3.12/site-packages/django/template/base.py", line 1005, in render
    return SafeString("".join([node.render_annotated(context) for node in self]))
                               ^^^^^^^^^^^^^^^^^^^^^^^^^^^^^^
  File "/Users/aliosmanyilmaz/opt/anaconda3/envs/shoe/lib/python3.12/site-packages/django/template/base.py", line 966, in render_annotated
    return self.render(context)
           ^^^^^^^^^^^^^^^^^^^^
  File "/Users/aliosmanyilmaz/opt/anaconda3/envs/shoe/lib/python3.12/site-packages/django/template/defaulttags.py", line 238, in render
    nodelist.append(node.render_annotated(context))
                    ^^^^^^^^^^^^^^^^^^^^^^^^^^^^^^
  File "/Users/aliosmanyilmaz/opt/anaconda3/envs/shoe/lib/python3.12/site-packages/django/template/base.py", line 966, in render_annotated
    return self.render(context)
           ^^^^^^^^^^^^^^^^^^^^
  File "/Users/aliosmanyilmaz/opt/anaconda3/envs/shoe/lib/python3.12/site-packages/django/template/loader_tags.py", line 208, in render
    return template.render(context)
           ^^^^^^^^^^^^^^^^^^^^^^^^
  File "/Users/aliosmanyilmaz/opt/anaconda3/envs/shoe/lib/python3.12/site-packages/django/template/base.py", line 177, in render
    return self._render(context)
           ^^^^^^^^^^^^^^^^^^^^^
  File "/Users/aliosmanyilmaz/opt/anaconda3/envs/shoe/lib/python3.12/site-packages/django/template/base.py", line 167, in _render
    return self.nodelist.render(context)
           ^^^^^^^^^^^^^^^^^^^^^^^^^^^^^
  File "/Users/aliosmanyilmaz/opt/anaconda3/envs/shoe/lib/python3.12/site-packages/django/template/base.py", line 1005, in render
    return SafeString("".join([node.render_annotated(context) for node in self]))
                               ^^^^^^^^^^^^^^^^^^^^^^^^^^^^^^
  File "/Users/aliosmanyilmaz/opt/anaconda3/envs/shoe/lib/python3.12/site-packages/django/template/base.py", line 966, in render_annotated
    return self.render(context)
           ^^^^^^^^^^^^^^^^^^^^
  File "/Users/aliosmanyilmaz/opt/anaconda3/envs/shoe/lib/python3.12/site-packages/django/template/defaulttags.py", line 238, in render
    nodelist.append(node.render_annotated(context))
                    ^^^^^^^^^^^^^^^^^^^^^^^^^^^^^^
  File "/Users/aliosmanyilmaz/opt/anaconda3/envs/shoe/lib/python3.12/site-packages/django/template/base.py", line 966, in render_annotated
    return self.render(context)
           ^^^^^^^^^^^^^^^^^^^^
  File "/Users/aliosmanyilmaz/opt/anaconda3/envs/shoe/lib/python3.12/site-packages/django/template/defaulttags.py", line 238, in render
    nodelist.append(node.render_annotated(context))
                    ^^^^^^^^^^^^^^^^^^^^^^^^^^^^^^
  File "/Users/aliosmanyilmaz/opt/anaconda3/envs/shoe/lib/python3.12/site-packages/django/template/base.py", line 966, in render_annotated
    return self.render(context)
           ^^^^^^^^^^^^^^^^^^^^
  File "/Users/aliosmanyilmaz/opt/anaconda3/envs/shoe/lib/python3.12/site-packages/django/template/defaulttags.py", line 321, in render
    return nodelist.render(context)
           ^^^^^^^^^^^^^^^^^^^^^^^^
  File "/Users/aliosmanyilmaz/opt/anaconda3/envs/shoe/lib/python3.12/site-packages/django/template/base.py", line 1005, in render
    return SafeString("".join([node.render_annotated(context) for node in self]))
                               ^^^^^^^^^^^^^^^^^^^^^^^^^^^^^^
  File "/Users/aliosmanyilmaz/opt/anaconda3/envs/shoe/lib/python3.12/site-packages/django/template/base.py", line 966, in render_annotated
    return self.render(context)
           ^^^^^^^^^^^^^^^^^^^^
  File "/Users/aliosmanyilmaz/opt/anaconda3/envs/shoe/lib/python3.12/site-packages/django/template/defaulttags.py", line 321, in render
    return nodelist.render(context)
           ^^^^^^^^^^^^^^^^^^^^^^^^
  File "/Users/aliosmanyilmaz/opt/anaconda3/envs/shoe/lib/python3.12/site-packages/django/template/base.py", line 1005, in render
    return SafeString("".join([node.render_annotated(context) for node in self]))
                               ^^^^^^^^^^^^^^^^^^^^^^^^^^^^^^
  File "/Users/aliosmanyilmaz/opt/anaconda3/envs/shoe/lib/python3.12/site-packages/django/template/base.py", line 966, in render_annotated
    return self.render(context)
           ^^^^^^^^^^^^^^^^^^^^
  File "/Users/aliosmanyilmaz/opt/anaconda3/envs/shoe/lib/python3.12/site-packages/django/template/base.py", line 1070, in render
    return render_value_in_context(output, context)
           ^^^^^^^^^^^^^^^^^^^^^^^^^^^^^^^^^^^^^^^^
  File "/Users/aliosmanyilmaz/opt/anaconda3/envs/shoe/lib/python3.12/site-packages/django/template/base.py", line 1047, in render_value_in_context
    value = str(value)
            ^^^^^^^^^^
  File "/Users/aliosmanyilmaz/opt/anaconda3/envs/shoe/lib/python3.12/site-packages/django/utils/html.py", line 420, in <lambda>
    klass.__str__ = lambda self: mark_safe(klass_str(self))
                                           ^^^^^^^^^^^^^^^
  File "/Users/aliosmanyilmaz/opt/anaconda3/envs/shoe/lib/python3.12/site-packages/django/forms/boundfield.py", line 34, in __str__
    return self.as_widget()
           ^^^^^^^^^^^^^^^^
  File "/Users/aliosmanyilmaz/opt/anaconda3/envs/shoe/lib/python3.12/site-packages/django/forms/boundfield.py", line 107, in as_widget
    return widget.render(
           ^^^^^^^^^^^^^^
  File "/Users/aliosmanyilmaz/opt/anaconda3/envs/shoe/lib/python3.12/site-packages/django/forms/widgets.py", line 280, in render
    context = self.get_context(name, value, attrs)
              ^^^^^^^^^^^^^^^^^^^^^^^^^^^^^^^^^^^^
  File "/Users/aliosmanyilmaz/opt/anaconda3/envs/shoe/lib/python3.12/site-packages/django/contrib/admin/widgets.py", line 320, in get_context
    "rendered_widget": self.widget.render(name, value, attrs),
                       ^^^^^^^^^^^^^^^^^^^^^^^^^^^^^^^^^^^^^^
  File "/Users/aliosmanyilmaz/opt/anaconda3/envs/shoe/lib/python3.12/site-packages/django/forms/widgets.py", line 280, in render
    context = self.get_context(name, value, attrs)
              ^^^^^^^^^^^^^^^^^^^^^^^^^^^^^^^^^^^^
  File "/Users/aliosmanyilmaz/opt/anaconda3/envs/shoe/lib/python3.12/site-packages/django/forms/widgets.py", line 758, in get_context
    context = super().get_context(name, value, attrs)
              ^^^^^^^^^^^^^^^^^^^^^^^^^^^^^^^^^^^^^^^
  File "/Users/aliosmanyilmaz/opt/anaconda3/envs/shoe/lib/python3.12/site-packages/django/forms/widgets.py", line 717, in get_context
    context["widget"]["optgroups"] = self.optgroups(
                                     ^^^^^^^^^^^^^^^
  File "/Users/aliosmanyilmaz/opt/anaconda3/envs/shoe/lib/python3.12/site-packages/django/forms/widgets.py", line 657, in optgroups
    for index, (option_value, option_label) in enumerate(self.choices):
  File "/Users/aliosmanyilmaz/opt/anaconda3/envs/shoe/lib/python3.12/site-packages/django/forms/models.py", line 1403, in __iter__
    for obj in queryset:
  File "/Users/aliosmanyilmaz/opt/anaconda3/envs/shoe/lib/python3.12/site-packages/django/db/models/query.py", line 516, in _iterator
    yield from iterable
  File "/Users/aliosmanyilmaz/opt/anaconda3/envs/shoe/lib/python3.12/site-packages/django/db/models/query.py", line 91, in __iter__
    results = compiler.execute_sql(
              ^^^^^^^^^^^^^^^^^^^^^
  File "/Users/aliosmanyilmaz/opt/anaconda3/envs/shoe/lib/python3.12/site-packages/silk/sql.py", line 96, in execute_sql
    query_dict['analysis'] = _explain_query(self.connection, q, params)
                             ^^^^^^^^^^^^^^^^^^^^^^^^^^^^^^^^^^^^^^^^^^
  File "/Users/aliosmanyilmaz/opt/anaconda3/envs/shoe/lib/python3.12/site-packages/silk/sql.py", line 58, in _explain_query
    cur.execute(prefixed_query, params)
  File "/Users/aliosmanyilmaz/opt/anaconda3/envs/shoe/lib/python3.12/site-packages/django/db/backends/utils.py", line 102, in execute
    return super().execute(sql, params)
           ^^^^^^^^^^^^^^^^^^^^^^^^^^^^
  File "/Users/aliosmanyilmaz/opt/anaconda3/envs/shoe/lib/python3.12/site-packages/sentry_sdk/integrations/django/__init__.py", line 641, in execute
    result = real_execute(self, sql, params)
             ^^^^^^^^^^^^^^^^^^^^^^^^^^^^^^^
  File "/Users/aliosmanyilmaz/opt/anaconda3/envs/shoe/lib/python3.12/site-packages/django/db/backends/utils.py", line 67, in execute
    return self._execute_with_wrappers(
           ^^^^^^^^^^^^^^^^^^^^^^^^^^^^
  File "/Users/aliosmanyilmaz/opt/anaconda3/envs/shoe/lib/python3.12/site-packages/django/db/backends/utils.py", line 80, in _execute_with_wrappers
    return executor(sql, params, many, context)
           ^^^^^^^^^^^^^^^^^^^^^^^^^^^^^^^^^^^^
  File "/Users/aliosmanyilmaz/opt/anaconda3/envs/shoe/lib/python3.12/site-packages/django/db/backends/utils.py", line 84, in _execute
    with self.db.wrap_database_errors:
  File "/Users/aliosmanyilmaz/opt/anaconda3/envs/shoe/lib/python3.12/site-packages/django/db/utils.py", line 91, in __exit__
    raise dj_exc_value.with_traceback(traceback) from exc_value
  File "/Users/aliosmanyilmaz/opt/anaconda3/envs/shoe/lib/python3.12/site-packages/django/db/backends/utils.py", line 89, in _execute
    return self.cursor.execute(sql, params)
           ^^^^^^^^^^^^^^^^^^^^^^^^^^^^^^^^
  File "/Users/aliosmanyilmaz/opt/anaconda3/envs/shoe/lib/python3.12/site-packages/django/db/backends/sqlite3/base.py", line 328, in execute
    return super().execute(query, params)
           ^^^^^^^^^^^^^^^^^^^^^^^^^^^^^^
django.db.utils.OperationalError: no such column: api_category.image
ERROR 2023-12-16 12:38:27,354 basehttp "GET /admin/api/product/4/change/ HTTP/1.1" 500 745474
ERROR 2023-12-16 12:38:31,120 log Internal Server Error: /admin/api/category/
Traceback (most recent call last):
  File "/Users/aliosmanyilmaz/opt/anaconda3/envs/shoe/lib/python3.12/site-packages/django/db/backends/utils.py", line 89, in _execute
    return self.cursor.execute(sql, params)
           ^^^^^^^^^^^^^^^^^^^^^^^^^^^^^^^^
  File "/Users/aliosmanyilmaz/opt/anaconda3/envs/shoe/lib/python3.12/site-packages/django/db/backends/sqlite3/base.py", line 328, in execute
    return super().execute(query, params)
           ^^^^^^^^^^^^^^^^^^^^^^^^^^^^^^
sqlite3.OperationalError: no such column: api_category.image

The above exception was the direct cause of the following exception:

Traceback (most recent call last):
  File "/Users/aliosmanyilmaz/opt/anaconda3/envs/shoe/lib/python3.12/site-packages/silk/sql.py", line 89, in execute_sql
    return self._execute_sql(*args, **kwargs)
           ^^^^^^^^^^^^^^^^^^^^^^^^^^^^^^^^^^
  File "/Users/aliosmanyilmaz/opt/anaconda3/envs/shoe/lib/python3.12/site-packages/django/db/models/sql/compiler.py", line 1562, in execute_sql
    cursor.execute(sql, params)
  File "/Users/aliosmanyilmaz/opt/anaconda3/envs/shoe/lib/python3.12/site-packages/django/db/backends/utils.py", line 102, in execute
    return super().execute(sql, params)
           ^^^^^^^^^^^^^^^^^^^^^^^^^^^^
  File "/Users/aliosmanyilmaz/opt/anaconda3/envs/shoe/lib/python3.12/site-packages/sentry_sdk/integrations/django/__init__.py", line 641, in execute
    result = real_execute(self, sql, params)
             ^^^^^^^^^^^^^^^^^^^^^^^^^^^^^^^
  File "/Users/aliosmanyilmaz/opt/anaconda3/envs/shoe/lib/python3.12/site-packages/django/db/backends/utils.py", line 67, in execute
    return self._execute_with_wrappers(
           ^^^^^^^^^^^^^^^^^^^^^^^^^^^^
  File "/Users/aliosmanyilmaz/opt/anaconda3/envs/shoe/lib/python3.12/site-packages/django/db/backends/utils.py", line 80, in _execute_with_wrappers
    return executor(sql, params, many, context)
           ^^^^^^^^^^^^^^^^^^^^^^^^^^^^^^^^^^^^
  File "/Users/aliosmanyilmaz/opt/anaconda3/envs/shoe/lib/python3.12/site-packages/django/db/backends/utils.py", line 84, in _execute
    with self.db.wrap_database_errors:
  File "/Users/aliosmanyilmaz/opt/anaconda3/envs/shoe/lib/python3.12/site-packages/django/db/utils.py", line 91, in __exit__
    raise dj_exc_value.with_traceback(traceback) from exc_value
  File "/Users/aliosmanyilmaz/opt/anaconda3/envs/shoe/lib/python3.12/site-packages/django/db/backends/utils.py", line 89, in _execute
    return self.cursor.execute(sql, params)
           ^^^^^^^^^^^^^^^^^^^^^^^^^^^^^^^^
  File "/Users/aliosmanyilmaz/opt/anaconda3/envs/shoe/lib/python3.12/site-packages/django/db/backends/sqlite3/base.py", line 328, in execute
    return super().execute(query, params)
           ^^^^^^^^^^^^^^^^^^^^^^^^^^^^^^
django.db.utils.OperationalError: no such column: api_category.image

During handling of the above exception, another exception occurred:

Traceback (most recent call last):
  File "/Users/aliosmanyilmaz/opt/anaconda3/envs/shoe/lib/python3.12/site-packages/django/db/backends/utils.py", line 89, in _execute
    return self.cursor.execute(sql, params)
           ^^^^^^^^^^^^^^^^^^^^^^^^^^^^^^^^
  File "/Users/aliosmanyilmaz/opt/anaconda3/envs/shoe/lib/python3.12/site-packages/django/db/backends/sqlite3/base.py", line 328, in execute
    return super().execute(query, params)
           ^^^^^^^^^^^^^^^^^^^^^^^^^^^^^^
sqlite3.OperationalError: no such column: api_category.image

The above exception was the direct cause of the following exception:

Traceback (most recent call last):
  File "/Users/aliosmanyilmaz/opt/anaconda3/envs/shoe/lib/python3.12/site-packages/django/core/handlers/exception.py", line 55, in inner
    response = get_response(request)
               ^^^^^^^^^^^^^^^^^^^^^
  File "/Users/aliosmanyilmaz/opt/anaconda3/envs/shoe/lib/python3.12/site-packages/django/core/handlers/base.py", line 197, in _get_response
    response = wrapped_callback(request, *callback_args, **callback_kwargs)
               ^^^^^^^^^^^^^^^^^^^^^^^^^^^^^^^^^^^^^^^^^^^^^^^^^^^^^^^^^^^^
  File "/Users/aliosmanyilmaz/opt/anaconda3/envs/shoe/lib/python3.12/site-packages/sentry_sdk/integrations/django/views.py", line 84, in sentry_wrapped_callback
    return callback(request, *args, **kwargs)
           ^^^^^^^^^^^^^^^^^^^^^^^^^^^^^^^^^^
  File "/Users/aliosmanyilmaz/opt/anaconda3/envs/shoe/lib/python3.12/site-packages/django/contrib/admin/options.py", line 688, in wrapper
    return self.admin_site.admin_view(view)(*args, **kwargs)
           ^^^^^^^^^^^^^^^^^^^^^^^^^^^^^^^^^^^^^^^^^^^^^^^^^
  File "/Users/aliosmanyilmaz/opt/anaconda3/envs/shoe/lib/python3.12/site-packages/django/utils/decorators.py", line 134, in _wrapper_view
    response = view_func(request, *args, **kwargs)
               ^^^^^^^^^^^^^^^^^^^^^^^^^^^^^^^^^^^
  File "/Users/aliosmanyilmaz/opt/anaconda3/envs/shoe/lib/python3.12/site-packages/django/views/decorators/cache.py", line 62, in _wrapper_view_func
    response = view_func(request, *args, **kwargs)
               ^^^^^^^^^^^^^^^^^^^^^^^^^^^^^^^^^^^
  File "/Users/aliosmanyilmaz/opt/anaconda3/envs/shoe/lib/python3.12/site-packages/django/contrib/admin/sites.py", line 242, in inner
    return view(request, *args, **kwargs)
           ^^^^^^^^^^^^^^^^^^^^^^^^^^^^^^
  File "/Users/aliosmanyilmaz/opt/anaconda3/envs/shoe/lib/python3.12/site-packages/django/utils/decorators.py", line 46, in _wrapper
    return bound_method(*args, **kwargs)
           ^^^^^^^^^^^^^^^^^^^^^^^^^^^^^
  File "/Users/aliosmanyilmaz/opt/anaconda3/envs/shoe/lib/python3.12/site-packages/django/utils/decorators.py", line 134, in _wrapper_view
    response = view_func(request, *args, **kwargs)
               ^^^^^^^^^^^^^^^^^^^^^^^^^^^^^^^^^^^
  File "/Users/aliosmanyilmaz/opt/anaconda3/envs/shoe/lib/python3.12/site-packages/django/contrib/admin/options.py", line 2065, in changelist_view
    "selection_note": _("0 of %(cnt)s selected") % {"cnt": len(cl.result_list)},
                                                           ^^^^^^^^^^^^^^^^^^^
  File "/Users/aliosmanyilmaz/opt/anaconda3/envs/shoe/lib/python3.12/site-packages/django/db/models/query.py", line 380, in __len__
    self._fetch_all()
  File "/Users/aliosmanyilmaz/opt/anaconda3/envs/shoe/lib/python3.12/site-packages/django/db/models/query.py", line 1881, in _fetch_all
    self._result_cache = list(self._iterable_class(self))
                         ^^^^^^^^^^^^^^^^^^^^^^^^^^^^^^^^
  File "/Users/aliosmanyilmaz/opt/anaconda3/envs/shoe/lib/python3.12/site-packages/django/db/models/query.py", line 91, in __iter__
    results = compiler.execute_sql(
              ^^^^^^^^^^^^^^^^^^^^^
  File "/Users/aliosmanyilmaz/opt/anaconda3/envs/shoe/lib/python3.12/site-packages/silk/sql.py", line 96, in execute_sql
    query_dict['analysis'] = _explain_query(self.connection, q, params)
                             ^^^^^^^^^^^^^^^^^^^^^^^^^^^^^^^^^^^^^^^^^^
  File "/Users/aliosmanyilmaz/opt/anaconda3/envs/shoe/lib/python3.12/site-packages/silk/sql.py", line 58, in _explain_query
    cur.execute(prefixed_query, params)
  File "/Users/aliosmanyilmaz/opt/anaconda3/envs/shoe/lib/python3.12/site-packages/django/db/backends/utils.py", line 102, in execute
    return super().execute(sql, params)
           ^^^^^^^^^^^^^^^^^^^^^^^^^^^^
  File "/Users/aliosmanyilmaz/opt/anaconda3/envs/shoe/lib/python3.12/site-packages/sentry_sdk/integrations/django/__init__.py", line 641, in execute
    result = real_execute(self, sql, params)
             ^^^^^^^^^^^^^^^^^^^^^^^^^^^^^^^
  File "/Users/aliosmanyilmaz/opt/anaconda3/envs/shoe/lib/python3.12/site-packages/django/db/backends/utils.py", line 67, in execute
    return self._execute_with_wrappers(
           ^^^^^^^^^^^^^^^^^^^^^^^^^^^^
  File "/Users/aliosmanyilmaz/opt/anaconda3/envs/shoe/lib/python3.12/site-packages/django/db/backends/utils.py", line 80, in _execute_with_wrappers
    return executor(sql, params, many, context)
           ^^^^^^^^^^^^^^^^^^^^^^^^^^^^^^^^^^^^
  File "/Users/aliosmanyilmaz/opt/anaconda3/envs/shoe/lib/python3.12/site-packages/django/db/backends/utils.py", line 84, in _execute
    with self.db.wrap_database_errors:
  File "/Users/aliosmanyilmaz/opt/anaconda3/envs/shoe/lib/python3.12/site-packages/django/db/utils.py", line 91, in __exit__
    raise dj_exc_value.with_traceback(traceback) from exc_value
  File "/Users/aliosmanyilmaz/opt/anaconda3/envs/shoe/lib/python3.12/site-packages/django/db/backends/utils.py", line 89, in _execute
    return self.cursor.execute(sql, params)
           ^^^^^^^^^^^^^^^^^^^^^^^^^^^^^^^^
  File "/Users/aliosmanyilmaz/opt/anaconda3/envs/shoe/lib/python3.12/site-packages/django/db/backends/sqlite3/base.py", line 328, in execute
    return super().execute(query, params)
           ^^^^^^^^^^^^^^^^^^^^^^^^^^^^^^
django.db.utils.OperationalError: no such column: api_category.image
ERROR 2023-12-16 12:38:31,136 basehttp "GET /admin/api/category/ HTTP/1.1" 500 254642
