ERROR 2023-12-15 19:02:21,808 log Internal Server Error: /api/products/
Traceback (most recent call last):
  File "/Users/aliosmanyilmaz/opt/anaconda3/envs/shoe/lib/python3.12/site-packages/django/core/handlers/exception.py", line 55, in inner
    response = get_response(request)
               ^^^^^^^^^^^^^^^^^^^^^
  File "/Users/aliosmanyilmaz/opt/anaconda3/envs/shoe/lib/python3.12/site-packages/django/core/handlers/base.py", line 197, in _get_response
    response = wrapped_callback(request, *callback_args, **callback_kwargs)
               ^^^^^^^^^^^^^^^^^^^^^^^^^^^^^^^^^^^^^^^^^^^^^^^^^^^^^^^^^^^^
  File "/Users/aliosmanyilmaz/opt/anaconda3/envs/shoe/lib/python3.12/site-packages/sentry_sdk/integrations/django/views.py", line 84, in sentry_wrapped_callback
    return callback(request, *args, **kwargs)
           ^^^^^^^^^^^^^^^^^^^^^^^^^^^^^^^^^^
  File "/Users/aliosmanyilmaz/opt/anaconda3/envs/shoe/lib/python3.12/site-packages/django/views/decorators/csrf.py", line 56, in wrapper_view
    return view_func(*args, **kwargs)
           ^^^^^^^^^^^^^^^^^^^^^^^^^^
  File "/Users/aliosmanyilmaz/opt/anaconda3/envs/shoe/lib/python3.12/site-packages/rest_framework/viewsets.py", line 125, in view
    return self.dispatch(request, *args, **kwargs)
           ^^^^^^^^^^^^^^^^^^^^^^^^^^^^^^^^^^^^^^^
  File "/Users/aliosmanyilmaz/opt/anaconda3/envs/shoe/lib/python3.12/site-packages/rest_framework/views.py", line 509, in dispatch
    response = self.handle_exception(exc)
               ^^^^^^^^^^^^^^^^^^^^^^^^^^
  File "/Users/aliosmanyilmaz/opt/anaconda3/envs/shoe/lib/python3.12/site-packages/rest_framework/views.py", line 469, in handle_exception
    self.raise_uncaught_exception(exc)
  File "/Users/aliosmanyilmaz/opt/anaconda3/envs/shoe/lib/python3.12/site-packages/rest_framework/views.py", line 480, in raise_uncaught_exception
    raise exc
  File "/Users/aliosmanyilmaz/opt/anaconda3/envs/shoe/lib/python3.12/site-packages/rest_framework/views.py", line 506, in dispatch
    response = handler(request, *args, **kwargs)
               ^^^^^^^^^^^^^^^^^^^^^^^^^^^^^^^^^
  File "/Users/aliosmanyilmaz/opt/anaconda3/envs/shoe/lib/python3.12/site-packages/rest_framework/mixins.py", line 46, in list
    return Response(serializer.data)
                    ^^^^^^^^^^^^^^^
  File "/Users/aliosmanyilmaz/opt/anaconda3/envs/shoe/lib/python3.12/site-packages/rest_framework/serializers.py", line 768, in data
    ret = super().data
          ^^^^^^^^^^^^
  File "/Users/aliosmanyilmaz/opt/anaconda3/envs/shoe/lib/python3.12/site-packages/rest_framework/serializers.py", line 253, in data
    self._data = self.to_representation(self.instance)
                 ^^^^^^^^^^^^^^^^^^^^^^^^^^^^^^^^^^^^^
  File "/Users/aliosmanyilmaz/opt/anaconda3/envs/shoe/lib/python3.12/site-packages/rest_framework/serializers.py", line 687, in to_representation
    self.child.to_representation(item) for item in iterable
    ^^^^^^^^^^^^^^^^^^^^^^^^^^^^^^^^^^
  File "/Users/aliosmanyilmaz/opt/anaconda3/envs/shoe/lib/python3.12/site-packages/rest_framework/serializers.py", line 507, in to_representation
    for field in fields:
  File "/Users/aliosmanyilmaz/opt/anaconda3/envs/shoe/lib/python3.12/site-packages/rest_framework/serializers.py", line 368, in _readable_fields
    for field in self.fields.values():
                 ^^^^^^^^^^^
  File "/Users/aliosmanyilmaz/opt/anaconda3/envs/shoe/lib/python3.12/site-packages/django/utils/functional.py", line 57, in __get__
    res = instance.__dict__[self.name] = self.func(instance)
                                         ^^^^^^^^^^^^^^^^^^^
  File "/Users/aliosmanyilmaz/opt/anaconda3/envs/shoe/lib/python3.12/site-packages/rest_framework/serializers.py", line 357, in fields
    fields[key] = value
    ~~~~~~^^^^^
  File "/Users/aliosmanyilmaz/opt/anaconda3/envs/shoe/lib/python3.12/site-packages/rest_framework/utils/serializer_helpers.py", line 169, in __setitem__
    field.bind(field_name=key, parent=self.serializer)
  File "/Users/aliosmanyilmaz/opt/anaconda3/envs/shoe/lib/python3.12/site-packages/rest_framework/fields.py", line 367, in bind
    assert self.source != field_name, (
AssertionError: It is redundant to specify `source='image_url'` on field 'CharField' in serializer 'ProductSerializer', because it is the same as the field name. Remove the `source` keyword argument.
ERROR 2023-12-15 19:02:21,823 basehttp "GET /api/products/ HTTP/1.1" 500 135859
ERROR 2023-12-15 19:02:21,872 log Internal Server Error: /api/products/
Traceback (most recent call last):
  File "/Users/aliosmanyilmaz/opt/anaconda3/envs/shoe/lib/python3.12/site-packages/django/core/handlers/exception.py", line 55, in inner
    response = get_response(request)
               ^^^^^^^^^^^^^^^^^^^^^
  File "/Users/aliosmanyilmaz/opt/anaconda3/envs/shoe/lib/python3.12/site-packages/django/core/handlers/base.py", line 197, in _get_response
    response = wrapped_callback(request, *callback_args, **callback_kwargs)
               ^^^^^^^^^^^^^^^^^^^^^^^^^^^^^^^^^^^^^^^^^^^^^^^^^^^^^^^^^^^^
  File "/Users/aliosmanyilmaz/opt/anaconda3/envs/shoe/lib/python3.12/site-packages/sentry_sdk/integrations/django/views.py", line 84, in sentry_wrapped_callback
    return callback(request, *args, **kwargs)
           ^^^^^^^^^^^^^^^^^^^^^^^^^^^^^^^^^^
  File "/Users/aliosmanyilmaz/opt/anaconda3/envs/shoe/lib/python3.12/site-packages/django/views/decorators/csrf.py", line 56, in wrapper_view
    return view_func(*args, **kwargs)
           ^^^^^^^^^^^^^^^^^^^^^^^^^^
  File "/Users/aliosmanyilmaz/opt/anaconda3/envs/shoe/lib/python3.12/site-packages/rest_framework/viewsets.py", line 125, in view
    return self.dispatch(request, *args, **kwargs)
           ^^^^^^^^^^^^^^^^^^^^^^^^^^^^^^^^^^^^^^^
  File "/Users/aliosmanyilmaz/opt/anaconda3/envs/shoe/lib/python3.12/site-packages/rest_framework/views.py", line 509, in dispatch
    response = self.handle_exception(exc)
               ^^^^^^^^^^^^^^^^^^^^^^^^^^
  File "/Users/aliosmanyilmaz/opt/anaconda3/envs/shoe/lib/python3.12/site-packages/rest_framework/views.py", line 469, in handle_exception
    self.raise_uncaught_exception(exc)
  File "/Users/aliosmanyilmaz/opt/anaconda3/envs/shoe/lib/python3.12/site-packages/rest_framework/views.py", line 480, in raise_uncaught_exception
    raise exc
  File "/Users/aliosmanyilmaz/opt/anaconda3/envs/shoe/lib/python3.12/site-packages/rest_framework/views.py", line 506, in dispatch
    response = handler(request, *args, **kwargs)
               ^^^^^^^^^^^^^^^^^^^^^^^^^^^^^^^^^
  File "/Users/aliosmanyilmaz/opt/anaconda3/envs/shoe/lib/python3.12/site-packages/rest_framework/mixins.py", line 46, in list
    return Response(serializer.data)
                    ^^^^^^^^^^^^^^^
  File "/Users/aliosmanyilmaz/opt/anaconda3/envs/shoe/lib/python3.12/site-packages/rest_framework/serializers.py", line 768, in data
    ret = super().data
          ^^^^^^^^^^^^
  File "/Users/aliosmanyilmaz/opt/anaconda3/envs/shoe/lib/python3.12/site-packages/rest_framework/serializers.py", line 253, in data
    self._data = self.to_representation(self.instance)
                 ^^^^^^^^^^^^^^^^^^^^^^^^^^^^^^^^^^^^^
  File "/Users/aliosmanyilmaz/opt/anaconda3/envs/shoe/lib/python3.12/site-packages/rest_framework/serializers.py", line 687, in to_representation
    self.child.to_representation(item) for item in iterable
    ^^^^^^^^^^^^^^^^^^^^^^^^^^^^^^^^^^
  File "/Users/aliosmanyilmaz/opt/anaconda3/envs/shoe/lib/python3.12/site-packages/rest_framework/serializers.py", line 507, in to_representation
    for field in fields:
  File "/Users/aliosmanyilmaz/opt/anaconda3/envs/shoe/lib/python3.12/site-packages/rest_framework/serializers.py", line 368, in _readable_fields
    for field in self.fields.values():
                 ^^^^^^^^^^^
  File "/Users/aliosmanyilmaz/opt/anaconda3/envs/shoe/lib/python3.12/site-packages/django/utils/functional.py", line 57, in __get__
    res = instance.__dict__[self.name] = self.func(instance)
                                         ^^^^^^^^^^^^^^^^^^^
  File "/Users/aliosmanyilmaz/opt/anaconda3/envs/shoe/lib/python3.12/site-packages/rest_framework/serializers.py", line 357, in fields
    fields[key] = value
    ~~~~~~^^^^^
  File "/Users/aliosmanyilmaz/opt/anaconda3/envs/shoe/lib/python3.12/site-packages/rest_framework/utils/serializer_helpers.py", line 169, in __setitem__
    field.bind(field_name=key, parent=self.serializer)
  File "/Users/aliosmanyilmaz/opt/anaconda3/envs/shoe/lib/python3.12/site-packages/rest_framework/fields.py", line 367, in bind
    assert self.source != field_name, (
AssertionError: It is redundant to specify `source='image_url'` on field 'CharField' in serializer 'ProductSerializer', because it is the same as the field name. Remove the `source` keyword argument.
ERROR 2023-12-15 19:02:21,884 basehttp "GET /api/products/ HTTP/1.1" 500 135859
ERROR 2023-12-15 19:03:46,033 log Internal Server Error: /api/products/
Traceback (most recent call last):
  File "/Users/aliosmanyilmaz/opt/anaconda3/envs/shoe/lib/python3.12/site-packages/django/core/handlers/exception.py", line 55, in inner
    response = get_response(request)
               ^^^^^^^^^^^^^^^^^^^^^
  File "/Users/aliosmanyilmaz/opt/anaconda3/envs/shoe/lib/python3.12/site-packages/django/core/handlers/base.py", line 197, in _get_response
    response = wrapped_callback(request, *callback_args, **callback_kwargs)
               ^^^^^^^^^^^^^^^^^^^^^^^^^^^^^^^^^^^^^^^^^^^^^^^^^^^^^^^^^^^^
  File "/Users/aliosmanyilmaz/opt/anaconda3/envs/shoe/lib/python3.12/site-packages/sentry_sdk/integrations/django/views.py", line 84, in sentry_wrapped_callback
    return callback(request, *args, **kwargs)
           ^^^^^^^^^^^^^^^^^^^^^^^^^^^^^^^^^^
  File "/Users/aliosmanyilmaz/opt/anaconda3/envs/shoe/lib/python3.12/site-packages/django/views/decorators/csrf.py", line 56, in wrapper_view
    return view_func(*args, **kwargs)
           ^^^^^^^^^^^^^^^^^^^^^^^^^^
  File "/Users/aliosmanyilmaz/opt/anaconda3/envs/shoe/lib/python3.12/site-packages/rest_framework/viewsets.py", line 125, in view
    return self.dispatch(request, *args, **kwargs)
           ^^^^^^^^^^^^^^^^^^^^^^^^^^^^^^^^^^^^^^^
  File "/Users/aliosmanyilmaz/opt/anaconda3/envs/shoe/lib/python3.12/site-packages/rest_framework/views.py", line 509, in dispatch
    response = self.handle_exception(exc)
               ^^^^^^^^^^^^^^^^^^^^^^^^^^
  File "/Users/aliosmanyilmaz/opt/anaconda3/envs/shoe/lib/python3.12/site-packages/rest_framework/views.py", line 469, in handle_exception
    self.raise_uncaught_exception(exc)
  File "/Users/aliosmanyilmaz/opt/anaconda3/envs/shoe/lib/python3.12/site-packages/rest_framework/views.py", line 480, in raise_uncaught_exception
    raise exc
  File "/Users/aliosmanyilmaz/opt/anaconda3/envs/shoe/lib/python3.12/site-packages/rest_framework/views.py", line 506, in dispatch
    response = handler(request, *args, **kwargs)
               ^^^^^^^^^^^^^^^^^^^^^^^^^^^^^^^^^
  File "/Users/aliosmanyilmaz/opt/anaconda3/envs/shoe/lib/python3.12/site-packages/rest_framework/mixins.py", line 46, in list
    return Response(serializer.data)
                    ^^^^^^^^^^^^^^^
  File "/Users/aliosmanyilmaz/opt/anaconda3/envs/shoe/lib/python3.12/site-packages/rest_framework/serializers.py", line 768, in data
    ret = super().data
          ^^^^^^^^^^^^
  File "/Users/aliosmanyilmaz/opt/anaconda3/envs/shoe/lib/python3.12/site-packages/rest_framework/serializers.py", line 253, in data
    self._data = self.to_representation(self.instance)
                 ^^^^^^^^^^^^^^^^^^^^^^^^^^^^^^^^^^^^^
  File "/Users/aliosmanyilmaz/opt/anaconda3/envs/shoe/lib/python3.12/site-packages/rest_framework/serializers.py", line 687, in to_representation
    self.child.to_representation(item) for item in iterable
    ^^^^^^^^^^^^^^^^^^^^^^^^^^^^^^^^^^
  File "/Users/aliosmanyilmaz/opt/anaconda3/envs/shoe/lib/python3.12/site-packages/rest_framework/serializers.py", line 507, in to_representation
    for field in fields:
  File "/Users/aliosmanyilmaz/opt/anaconda3/envs/shoe/lib/python3.12/site-packages/rest_framework/serializers.py", line 368, in _readable_fields
    for field in self.fields.values():
                 ^^^^^^^^^^^
  File "/Users/aliosmanyilmaz/opt/anaconda3/envs/shoe/lib/python3.12/site-packages/django/utils/functional.py", line 57, in __get__
    res = instance.__dict__[self.name] = self.func(instance)
                                         ^^^^^^^^^^^^^^^^^^^
  File "/Users/aliosmanyilmaz/opt/anaconda3/envs/shoe/lib/python3.12/site-packages/rest_framework/serializers.py", line 357, in fields
    fields[key] = value
    ~~~~~~^^^^^
  File "/Users/aliosmanyilmaz/opt/anaconda3/envs/shoe/lib/python3.12/site-packages/rest_framework/utils/serializer_helpers.py", line 169, in __setitem__
    field.bind(field_name=key, parent=self.serializer)
  File "/Users/aliosmanyilmaz/opt/anaconda3/envs/shoe/lib/python3.12/site-packages/rest_framework/fields.py", line 367, in bind
    assert self.source != field_name, (
AssertionError: It is redundant to specify `source='image_url'` on field 'CharField' in serializer 'ProductSerializer', because it is the same as the field name. Remove the `source` keyword argument.
ERROR 2023-12-15 19:03:46,049 basehttp "GET /api/products/ HTTP/1.1" 500 136833
ERROR 2023-12-15 19:04:31,744 log Internal Server Error: /api/products/
Traceback (most recent call last):
  File "/Users/aliosmanyilmaz/opt/anaconda3/envs/shoe/lib/python3.12/site-packages/django/core/handlers/exception.py", line 55, in inner
    response = get_response(request)
               ^^^^^^^^^^^^^^^^^^^^^
  File "/Users/aliosmanyilmaz/opt/anaconda3/envs/shoe/lib/python3.12/site-packages/django/core/handlers/base.py", line 197, in _get_response
    response = wrapped_callback(request, *callback_args, **callback_kwargs)
               ^^^^^^^^^^^^^^^^^^^^^^^^^^^^^^^^^^^^^^^^^^^^^^^^^^^^^^^^^^^^
  File "/Users/aliosmanyilmaz/opt/anaconda3/envs/shoe/lib/python3.12/site-packages/sentry_sdk/integrations/django/views.py", line 84, in sentry_wrapped_callback
    return callback(request, *args, **kwargs)
           ^^^^^^^^^^^^^^^^^^^^^^^^^^^^^^^^^^
  File "/Users/aliosmanyilmaz/opt/anaconda3/envs/shoe/lib/python3.12/site-packages/django/views/decorators/csrf.py", line 56, in wrapper_view
    return view_func(*args, **kwargs)
           ^^^^^^^^^^^^^^^^^^^^^^^^^^
  File "/Users/aliosmanyilmaz/opt/anaconda3/envs/shoe/lib/python3.12/site-packages/rest_framework/viewsets.py", line 125, in view
    return self.dispatch(request, *args, **kwargs)
           ^^^^^^^^^^^^^^^^^^^^^^^^^^^^^^^^^^^^^^^
  File "/Users/aliosmanyilmaz/opt/anaconda3/envs/shoe/lib/python3.12/site-packages/rest_framework/views.py", line 509, in dispatch
    response = self.handle_exception(exc)
               ^^^^^^^^^^^^^^^^^^^^^^^^^^
  File "/Users/aliosmanyilmaz/opt/anaconda3/envs/shoe/lib/python3.12/site-packages/rest_framework/views.py", line 469, in handle_exception
    self.raise_uncaught_exception(exc)
  File "/Users/aliosmanyilmaz/opt/anaconda3/envs/shoe/lib/python3.12/site-packages/rest_framework/views.py", line 480, in raise_uncaught_exception
    raise exc
  File "/Users/aliosmanyilmaz/opt/anaconda3/envs/shoe/lib/python3.12/site-packages/rest_framework/views.py", line 506, in dispatch
    response = handler(request, *args, **kwargs)
               ^^^^^^^^^^^^^^^^^^^^^^^^^^^^^^^^^
  File "/Users/aliosmanyilmaz/opt/anaconda3/envs/shoe/lib/python3.12/site-packages/rest_framework/mixins.py", line 46, in list
    return Response(serializer.data)
                    ^^^^^^^^^^^^^^^
  File "/Users/aliosmanyilmaz/opt/anaconda3/envs/shoe/lib/python3.12/site-packages/rest_framework/serializers.py", line 768, in data
    ret = super().data
          ^^^^^^^^^^^^
  File "/Users/aliosmanyilmaz/opt/anaconda3/envs/shoe/lib/python3.12/site-packages/rest_framework/serializers.py", line 253, in data
    self._data = self.to_representation(self.instance)
                 ^^^^^^^^^^^^^^^^^^^^^^^^^^^^^^^^^^^^^
  File "/Users/aliosmanyilmaz/opt/anaconda3/envs/shoe/lib/python3.12/site-packages/rest_framework/serializers.py", line 687, in to_representation
    self.child.to_representation(item) for item in iterable
    ^^^^^^^^^^^^^^^^^^^^^^^^^^^^^^^^^^
  File "/Users/aliosmanyilmaz/opt/anaconda3/envs/shoe/lib/python3.12/site-packages/rest_framework/serializers.py", line 507, in to_representation
    for field in fields:
  File "/Users/aliosmanyilmaz/opt/anaconda3/envs/shoe/lib/python3.12/site-packages/rest_framework/serializers.py", line 368, in _readable_fields
    for field in self.fields.values():
                 ^^^^^^^^^^^
  File "/Users/aliosmanyilmaz/opt/anaconda3/envs/shoe/lib/python3.12/site-packages/django/utils/functional.py", line 57, in __get__
    res = instance.__dict__[self.name] = self.func(instance)
                                         ^^^^^^^^^^^^^^^^^^^
  File "/Users/aliosmanyilmaz/opt/anaconda3/envs/shoe/lib/python3.12/site-packages/rest_framework/serializers.py", line 357, in fields
    fields[key] = value
    ~~~~~~^^^^^
  File "/Users/aliosmanyilmaz/opt/anaconda3/envs/shoe/lib/python3.12/site-packages/rest_framework/utils/serializer_helpers.py", line 169, in __setitem__
    field.bind(field_name=key, parent=self.serializer)
  File "/Users/aliosmanyilmaz/opt/anaconda3/envs/shoe/lib/python3.12/site-packages/rest_framework/fields.py", line 367, in bind
    assert self.source != field_name, (
AssertionError: It is redundant to specify `source='image_url'` on field 'CharField' in serializer 'ProductSerializer', because it is the same as the field name. Remove the `source` keyword argument.
ERROR 2023-12-15 19:04:31,768 basehttp "GET /api/products/ HTTP/1.1" 500 135949
ERROR 2023-12-15 19:04:31,850 log Internal Server Error: /api/products/
Traceback (most recent call last):
  File "/Users/aliosmanyilmaz/opt/anaconda3/envs/shoe/lib/python3.12/site-packages/django/core/handlers/exception.py", line 55, in inner
    response = get_response(request)
               ^^^^^^^^^^^^^^^^^^^^^
  File "/Users/aliosmanyilmaz/opt/anaconda3/envs/shoe/lib/python3.12/site-packages/django/core/handlers/base.py", line 197, in _get_response
    response = wrapped_callback(request, *callback_args, **callback_kwargs)
               ^^^^^^^^^^^^^^^^^^^^^^^^^^^^^^^^^^^^^^^^^^^^^^^^^^^^^^^^^^^^
  File "/Users/aliosmanyilmaz/opt/anaconda3/envs/shoe/lib/python3.12/site-packages/sentry_sdk/integrations/django/views.py", line 84, in sentry_wrapped_callback
    return callback(request, *args, **kwargs)
           ^^^^^^^^^^^^^^^^^^^^^^^^^^^^^^^^^^
  File "/Users/aliosmanyilmaz/opt/anaconda3/envs/shoe/lib/python3.12/site-packages/django/views/decorators/csrf.py", line 56, in wrapper_view
    return view_func(*args, **kwargs)
           ^^^^^^^^^^^^^^^^^^^^^^^^^^
  File "/Users/aliosmanyilmaz/opt/anaconda3/envs/shoe/lib/python3.12/site-packages/rest_framework/viewsets.py", line 125, in view
    return self.dispatch(request, *args, **kwargs)
           ^^^^^^^^^^^^^^^^^^^^^^^^^^^^^^^^^^^^^^^
  File "/Users/aliosmanyilmaz/opt/anaconda3/envs/shoe/lib/python3.12/site-packages/rest_framework/views.py", line 509, in dispatch
    response = self.handle_exception(exc)
               ^^^^^^^^^^^^^^^^^^^^^^^^^^
  File "/Users/aliosmanyilmaz/opt/anaconda3/envs/shoe/lib/python3.12/site-packages/rest_framework/views.py", line 469, in handle_exception
    self.raise_uncaught_exception(exc)
  File "/Users/aliosmanyilmaz/opt/anaconda3/envs/shoe/lib/python3.12/site-packages/rest_framework/views.py", line 480, in raise_uncaught_exception
    raise exc
  File "/Users/aliosmanyilmaz/opt/anaconda3/envs/shoe/lib/python3.12/site-packages/rest_framework/views.py", line 506, in dispatch
    response = handler(request, *args, **kwargs)
               ^^^^^^^^^^^^^^^^^^^^^^^^^^^^^^^^^
  File "/Users/aliosmanyilmaz/opt/anaconda3/envs/shoe/lib/python3.12/site-packages/rest_framework/mixins.py", line 46, in list
    return Response(serializer.data)
                    ^^^^^^^^^^^^^^^
  File "/Users/aliosmanyilmaz/opt/anaconda3/envs/shoe/lib/python3.12/site-packages/rest_framework/serializers.py", line 768, in data
    ret = super().data
          ^^^^^^^^^^^^
  File "/Users/aliosmanyilmaz/opt/anaconda3/envs/shoe/lib/python3.12/site-packages/rest_framework/serializers.py", line 253, in data
    self._data = self.to_representation(self.instance)
                 ^^^^^^^^^^^^^^^^^^^^^^^^^^^^^^^^^^^^^
  File "/Users/aliosmanyilmaz/opt/anaconda3/envs/shoe/lib/python3.12/site-packages/rest_framework/serializers.py", line 687, in to_representation
    self.child.to_representation(item) for item in iterable
    ^^^^^^^^^^^^^^^^^^^^^^^^^^^^^^^^^^
  File "/Users/aliosmanyilmaz/opt/anaconda3/envs/shoe/lib/python3.12/site-packages/rest_framework/serializers.py", line 507, in to_representation
    for field in fields:
  File "/Users/aliosmanyilmaz/opt/anaconda3/envs/shoe/lib/python3.12/site-packages/rest_framework/serializers.py", line 368, in _readable_fields
    for field in self.fields.values():
                 ^^^^^^^^^^^
  File "/Users/aliosmanyilmaz/opt/anaconda3/envs/shoe/lib/python3.12/site-packages/django/utils/functional.py", line 57, in __get__
    res = instance.__dict__[self.name] = self.func(instance)
                                         ^^^^^^^^^^^^^^^^^^^
  File "/Users/aliosmanyilmaz/opt/anaconda3/envs/shoe/lib/python3.12/site-packages/rest_framework/serializers.py", line 357, in fields
    fields[key] = value
    ~~~~~~^^^^^
  File "/Users/aliosmanyilmaz/opt/anaconda3/envs/shoe/lib/python3.12/site-packages/rest_framework/utils/serializer_helpers.py", line 169, in __setitem__
    field.bind(field_name=key, parent=self.serializer)
  File "/Users/aliosmanyilmaz/opt/anaconda3/envs/shoe/lib/python3.12/site-packages/rest_framework/fields.py", line 367, in bind
    assert self.source != field_name, (
AssertionError: It is redundant to specify `source='image_url'` on field 'CharField' in serializer 'ProductSerializer', because it is the same as the field name. Remove the `source` keyword argument.
ERROR 2023-12-15 19:04:31,868 basehttp "GET /api/products/ HTTP/1.1" 500 135949
ERROR 2023-12-15 19:04:41,905 log Internal Server Error: /api/products/
Traceback (most recent call last):
  File "/Users/aliosmanyilmaz/opt/anaconda3/envs/shoe/lib/python3.12/site-packages/django/core/handlers/exception.py", line 55, in inner
    response = get_response(request)
               ^^^^^^^^^^^^^^^^^^^^^
  File "/Users/aliosmanyilmaz/opt/anaconda3/envs/shoe/lib/python3.12/site-packages/django/core/handlers/base.py", line 197, in _get_response
    response = wrapped_callback(request, *callback_args, **callback_kwargs)
               ^^^^^^^^^^^^^^^^^^^^^^^^^^^^^^^^^^^^^^^^^^^^^^^^^^^^^^^^^^^^
  File "/Users/aliosmanyilmaz/opt/anaconda3/envs/shoe/lib/python3.12/site-packages/sentry_sdk/integrations/django/views.py", line 84, in sentry_wrapped_callback
    return callback(request, *args, **kwargs)
           ^^^^^^^^^^^^^^^^^^^^^^^^^^^^^^^^^^
  File "/Users/aliosmanyilmaz/opt/anaconda3/envs/shoe/lib/python3.12/site-packages/django/views/decorators/csrf.py", line 56, in wrapper_view
    return view_func(*args, **kwargs)
           ^^^^^^^^^^^^^^^^^^^^^^^^^^
  File "/Users/aliosmanyilmaz/opt/anaconda3/envs/shoe/lib/python3.12/site-packages/rest_framework/viewsets.py", line 125, in view
    return self.dispatch(request, *args, **kwargs)
           ^^^^^^^^^^^^^^^^^^^^^^^^^^^^^^^^^^^^^^^
  File "/Users/aliosmanyilmaz/opt/anaconda3/envs/shoe/lib/python3.12/site-packages/rest_framework/views.py", line 509, in dispatch
    response = self.handle_exception(exc)
               ^^^^^^^^^^^^^^^^^^^^^^^^^^
  File "/Users/aliosmanyilmaz/opt/anaconda3/envs/shoe/lib/python3.12/site-packages/rest_framework/views.py", line 469, in handle_exception
    self.raise_uncaught_exception(exc)
  File "/Users/aliosmanyilmaz/opt/anaconda3/envs/shoe/lib/python3.12/site-packages/rest_framework/views.py", line 480, in raise_uncaught_exception
    raise exc
  File "/Users/aliosmanyilmaz/opt/anaconda3/envs/shoe/lib/python3.12/site-packages/rest_framework/views.py", line 506, in dispatch
    response = handler(request, *args, **kwargs)
               ^^^^^^^^^^^^^^^^^^^^^^^^^^^^^^^^^
  File "/Users/aliosmanyilmaz/opt/anaconda3/envs/shoe/lib/python3.12/site-packages/rest_framework/mixins.py", line 46, in list
    return Response(serializer.data)
                    ^^^^^^^^^^^^^^^
  File "/Users/aliosmanyilmaz/opt/anaconda3/envs/shoe/lib/python3.12/site-packages/rest_framework/serializers.py", line 768, in data
    ret = super().data
          ^^^^^^^^^^^^
  File "/Users/aliosmanyilmaz/opt/anaconda3/envs/shoe/lib/python3.12/site-packages/rest_framework/serializers.py", line 253, in data
    self._data = self.to_representation(self.instance)
                 ^^^^^^^^^^^^^^^^^^^^^^^^^^^^^^^^^^^^^
  File "/Users/aliosmanyilmaz/opt/anaconda3/envs/shoe/lib/python3.12/site-packages/rest_framework/serializers.py", line 687, in to_representation
    self.child.to_representation(item) for item in iterable
    ^^^^^^^^^^^^^^^^^^^^^^^^^^^^^^^^^^
  File "/Users/aliosmanyilmaz/opt/anaconda3/envs/shoe/lib/python3.12/site-packages/rest_framework/serializers.py", line 507, in to_representation
    for field in fields:
  File "/Users/aliosmanyilmaz/opt/anaconda3/envs/shoe/lib/python3.12/site-packages/rest_framework/serializers.py", line 368, in _readable_fields
    for field in self.fields.values():
                 ^^^^^^^^^^^
  File "/Users/aliosmanyilmaz/opt/anaconda3/envs/shoe/lib/python3.12/site-packages/django/utils/functional.py", line 57, in __get__
    res = instance.__dict__[self.name] = self.func(instance)
                                         ^^^^^^^^^^^^^^^^^^^
  File "/Users/aliosmanyilmaz/opt/anaconda3/envs/shoe/lib/python3.12/site-packages/rest_framework/serializers.py", line 357, in fields
    fields[key] = value
    ~~~~~~^^^^^
  File "/Users/aliosmanyilmaz/opt/anaconda3/envs/shoe/lib/python3.12/site-packages/rest_framework/utils/serializer_helpers.py", line 169, in __setitem__
    field.bind(field_name=key, parent=self.serializer)
  File "/Users/aliosmanyilmaz/opt/anaconda3/envs/shoe/lib/python3.12/site-packages/rest_framework/fields.py", line 367, in bind
    assert self.source != field_name, (
AssertionError: It is redundant to specify `source='image_url'` on field 'CharField' in serializer 'ProductSerializer', because it is the same as the field name. Remove the `source` keyword argument.
ERROR 2023-12-15 19:04:41,934 basehttp "GET /api/products/ HTTP/1.1" 500 137060
